Workbook

Sheet Sheet
D1: MARKED IN YELLOW IS TICKET BOOKED BY THE COMPANY
D2: Last 5 years leave will be counted in calculation
A3: S.NO. | B3: Employee ID | C3: STAFF NAME | D3: JOINING DATE | E3: CALCULATE LEAVE FROM LAST 5 Years | F3: 2010 | G3: 2011 | H3: 2012 | I3: 2013 | J3: 2014 | K3: 2015 | L3: 2016 | M3: 2017 | N3: 2018 | O3: 2019 | P3: 2020 | Q3: 2021 | R3: 2022 | S3: 2023 | T3: 2024 | U3: 2025 | V3: 2026 | W3: last 5 years leave taken | X3: Avrg | Y3: LEAVE DUE | Z3: last 5 years | AA3: yrs | AB3: working yrs | AC3: TILL
A4: 1 | B4: IDFO-000 | C4: KANTESH GAGAN DAS NIHALACHANDANI | D4: 39295 | E4: 44197 | F4: 9 | G4: 20 | H4: 12 | I4: ='2013'!I3 -> 21 | J4: ='2014'!I3 -> 26 | K4: ='2015'!L4 -> 14 | L4: ='2016'!M4 -> 33 | N4: ='2018'!M2 -> 21 | O4: ='2019'!M2 -> 26 | P4: 0 | Q4: 21 | R4: 10 | S4: 36 | T4: 0 | U4: ='2025'!M2 -> 26 | V4: ='2026'!M2 -> 2 | W4: =SUM(P4:V4) -> 95 | X4: =W4/5 -> 19 | Y4: =SUM(30-X4)*AA4 -> 55.934247 | Z4: =AC4-E4 -> 1856 | AA4: =Z4/365 -> 5.0849315 | AB4: =SUM(AC4-D4)/365 -> 18.515068 | AC4: 46053
A5: 2 | B5: IDMO-032 | C5: PAWAN JAIKISHIN KOTAI | D5: 41883 | E5: 44197 | F5: join in sep 2014 | K5: ='2015'!L5 -> 0 | L5: ='2016'!M6 -> 23 | N5: ='2018'!M3 -> 0 | O5: ='2019'!M3 -> 28 | P5: 37 | Q5: 31 | R5: 22 | S5: 21 | T5: 24 | U5: ='2025'!M3 -> 24 | V5: ='2026'!M3 -> 14 | W5: =SUM(P5:V5) -> 173 | X5: =W5/5 -> 34.6 | Y5: =SUM(30-X5)*AA5 -> -23.390685 | Z5: =AC5-E5 -> 1856 | AA5: =Z5/365 -> 5.0849315 | AB5: =SUM(AC5-D5)/365 -> 11.424658 | AC5: 46053
A6: 3 | B6: IDMO-044 | C6: SANDEEP PULLANCHIODAN RAMATH SURENDRAN KURINHERI | D6: 42740 | E6: 44197 | F6: JOIN JAN 2017 | N6: ='2018'!M7 -> 21 | O6: ='2019'!M6 -> 41 | P6: 14 | Q6: 104 | R6: 0 | S6: 0 | T6: 0 | U6: ='2025'!M4 -> 10 | W6: =SUM(P6:U6) -> 128 | X6: =W6/5 -> 25.6 | Y6: =SUM(30-X6)*AA6 -> 22.687123 | Z6: =AC6-E6 -> 1882 | AA6: =Z6/365 -> 5.1561644 | AB6: =SUM(AC6-D6)/365 -> 9.1479452 | AC6: 46079
A7: 4 | B7: IDMO-133 | C7: AMAL SID | D7: 44762 | E7: 44869 | Q7: 0 | R7: 0 | S7: 0 | T7: 52 | U7: ='2025'!M5 -> 6 | V7: ='2026'!M5 -> 30 | W7: =SUM(P7:V7) -> 88 | X7: =W7/5 -> 17.6 | Y7: =SUM(30-X7)*AA7 -> 40.223562 | Z7: =AC7-E7 -> 1184 | AA7: =Z7/365 -> 3.2438356 | AB7: =SUM(AC7-D7)/365 -> 3.5369863 | AC7: 46053
A8: 5 | B8: IDMO-134 | C8: PRAJNA PUTTUR DIVAKARA | D8: 44866 | E8: 44932 | Q8: 0 | R8: 0 | S8: 0 | T8: 14 | U8: ='2025'!M142 -> 0 | W8: =SUM(P8:T8) -> 14 | X8: =W8/5 -> 2.8 | Y8: =SUM(30-X8)*AA8 -> 83.537534 | Z8: =AC8-E8 -> 1121 | AA8: =Z8/365 -> 3.0712329 | AB8: =SUM(AC8-D8)/365 -> 3.2520548 | AC8: 46053
A9: 6 | B9: IDMO-139 | C9: PRAJNA SACHIN POOJARY | D9: 44900 | E9: 44972 | R9: 0 | S9: 0 | T9: 14 | U9: ='2025'!M143 -> 0 | W9: =SUM(P9:V9) -> 14 | X9: =W9/5 -> 2.8 | Y9: =SUM(30-X9)*AA9 -> 80.556712 | Z9: =AC9-E9 -> 1081 | AA9: =Z9/365 -> 2.9616438 | AB9: =SUM(AC9-D9)/365 -> 3.1589041 | AC9: 46053
A10: 7 | B10: IDMO-197 | C10: NAINIKA GIRISH | D10: 45658 | E10: 45658 | U10: ='2025'!M6 -> 0 | W10: =SUM(P10:V10) -> 0 | AC10: 46053
A11: 8 | B11: IDMO-154 | C11: UMESH KUMAR PANDEY | D11: 45114 | E11: 45114 | Q11: 0 | R11: 0 | S11: 0 | T11: 0 | U11: ='2025'!M149 -> 0 | W11: =SUM(P11:V11) -> 0 | X11: =W11/5 -> 0 | Y11: =SUM(30-X11)*AA11 -> 77.178082 | Z11: =AC11-E11 -> 939 | AA11: =Z11/365 -> 2.5726027 | AB11: =SUM(AC11-D11)/365 -> 2.5726027 | AC11: 46053
A12: 9 | B12: IDMO-165 | C12: ADARSH VERNEKAR | D12: 45301 | E12: 45301 | Q12: 0 | R12: 0 | S12: 0 | T12: 0 | U12: ='2025'!M7 -> 28 | W12: =SUM(P12:V12) -> 28 | X12: =W12/5 -> 5.6 | Y12: =SUM(30-X12)*AA12 -> 50.270685 | Z12: =AC12-E12 -> 752 | AA12: =Z12/365 -> 2.060274 | AB12: =SUM(AC12-D12)/365 -> 2.060274 | AC12: 46053
A13: 10 | B13: IDMO-178 | C13: MELVIN THOMAS | D13: 45432 | E13: 45458 | Q13: 0 | R13: 0 | S13: 0 | T13: - | U13: - | V13: ='2026'!M8 -> 14 | W13: =SUM(P13:V13) -> 14 | X13: 7 | Y13: =SUM(30-X13)*AA13 -> 46 | Z13: =AC13-E13 -> 730 | AA13: =Z13/365 -> 2 | AB13: =SUM(AC13-D13)/365 -> 2.0712329 | AC13: 46188
A14: 11 | B14: IDMS-001 | C14: SANJAY MICHUMAL PUNJABI | D14: 39083 | E14: 44197 | F14: 8 | G14: 10 | H14: 5 | I14: ='2013'!I7 -> 4 | J14: ='2014'!I9 -> 5 | K14: ='2015'!L10 -> 10 | L14: ='2016'!M11 -> 5 | N14: ='2018'!M9 -> 0 | O14: ='2019'!M8 -> 4 | P14: 3 | Q14: 0 | R14: 15 | S14: 16 | T14: 8 | U14: ='2025'!M9 -> 0 | V14: ='2026'!M9 -> 7 | W14: =SUM(P14:V14) -> 49 | X14: =W14/5 -> 9.8 | Y14: =SUM(30-X14)*AA14 -> 102.71562 | Z14: =AC14-E14 -> 1856 | AA14: =Z14/365 -> 5.0849315 | AB14: =SUM(AC14-D14)/365 -> 19.09589 | AC14: 46053
A15: 12 | B15: IDMS-031 | C15: UMAIR RIAZ MUHAMMAD RIAZ SHOUQ | D15: 41852 | E15: 44197 | N15: ='2018'!M99 -> 0 | O15: ='2019'!M102 -> 16 | P15: 41 | Q15: 0 | R15: 0 | S15: 32 | T15: 0 | U15: ='2025'!M10 -> 0 | W15: =SUM(P15:T15) -> 73 | X15: =W15/5 -> 14.6 | Y15: =SUM(30-X15)*AA15 -> 78.307945 | Z15: =AC15-E15 -> 1856 | AA15: =Z15/365 -> 5.0849315 | AB15: =SUM(AC15-D15)/365 -> 11.509589 | AC15: 46053
A16: 13 | B16: IDMO-002 | C16: MAHESH CHAINANI RAMCHAND | D16: 39083 | E16: 44197 | F16: 21 | G16: 33 | H16: 14 | I16: ='2013'!I9 -> 15 | J16: ='2014'!I12 -> 11 | K16: ='2015'!L13 -> 31 | L16: ='2016'!M14 -> 34 | N16: ='2018'!M12 -> 18 | O16: ='2019'!M10 -> 13 | P16: 0 | Q16: 16 | R16: 23 | S16: 19 | T16: 12 | U16: ='2025'!M11 -> 15 | W16: =SUM(P16:T16) -> 70 | X16: =W16/5 -> 14 | Y16: =SUM(30-X16)*AA16 -> 81.358904 | Z16: =AC16-E16 -> 1856 | AA16: =Z16/365 -> 5.0849315 | AB16: =SUM(AC16-D16)/365 -> 19.09589 | AC16: 46053
A17: 14 | B17: IDMS-003 | C17: JITESH CHAWLA | D17: 39083 | E17: 44197 | F17: 89 | G17: 45 | H17: 13 | I17: ='2013'!I10 -> 29 | J17: ='2014'!I13 -> 14 | K17: ='2015'!L14 -> 31 | L17: ='2016'!M15 -> 23 | N17: ='2018'!M13 -> 13 | O17: ='2019'!M11 -> 0 | P17: 0 | Q17: 28 | R17: 16 | S17: 22 | T17: ='2024'!M11 -> 15 | U17: ='2025'!M12 -> 20 | W17: =SUM(P17:T17) -> 81 | X17: =W17/5 -> 16.2 | Y17: =SUM(30-X17)*AA17 -> 70.172055 | Z17: =AC17-E17 -> 1856 | AA17: =Z17/365 -> 5.0849315 | AB17: =SUM(AC17-D17)/365 -> 19.09589 | AC17: 46053
A18: 15 | B18: IDBS-012 | C18: VIJAY KUMAR ASHOK KUMAR | D18: 39142 | E18: 44197 | F18: 31 | G18: 6 | H18: 34 | I18: ='2013'!I11 -> 0 | J18: ='2014'!I14 -> 34 | K18: ='2015'!L15 -> 13 | L18: ='2016'!M16 -> 11 | N18: ='2018'!M14 -> 10 | O18: ='2019'!M12 -> 18 | P18: 1 | Q18: 0 | R18: 8 | S18: 37 | T18: 2 | U18: ='2025'!M13 -> 4 | W18: =SUM(P18:U18) -> 52 | X18: =W18/5 -> 10.4 | Y18: =SUM(30-X18)*AA18 -> 99.664658 | Z18: =AC18-E18 -> 1856 | AA18: =Z18/365 -> 5.0849315 | AB18: =SUM(AC18-D18)/365 -> 18.934247 | AC18: 46053
A19: 16 | B19: IDBO-036 | C19: ASHFAQ MUHAMMAD AHAMED | D19: 42036 | E19: 44197 | F19: JOIN IN 2015 | K19: ='2015'!L3 -> 5 | L19: ='2016'!M5 -> 20 | N19: ='2018'!M15 -> 51 | O19: ='2019'!M13 -> 22 | P19: 20 | Q19: 6 | R19: 60 | S19: 5 | T19: 13 | U19: ='2025'!M14 -> 0 | V19: ='2026'!M14 -> 14 | W19: =SUM(P19:T19) -> 104 | X19: =W19/5 -> 20.8 | Y19: =SUM(30-X19)*AA19 -> 46.78137 | Z19: =AC19-E19 -> 1856 | AA19: =Z19/365 -> 5.0849315 | AB19: =SUM(AC19-D19)/365 -> 11.005479 | AC19: 46053
A20: 17 | B20: IDMO-090 | C20: GAURAV NATHANI SANTOSH NATHANI | D20: 44317 | E20: 44317 | Q20: 16 | R20: 0 | S20: 6 | T20: 26 | U20: ='2025'!M15 -> 0 | W20: =SUM(P20:T20) -> 48 | X20: =W20/5 -> 9.6 | Y20: =SUM(30-X20)*AA20 -> 97.025753 | Z20: =AC20-E20 -> 1736 | AA20: =Z20/365 -> 4.7561644 | AB20: =SUM(AC20-D20)/365 -> 4.7561644 | AC20: 46053
A21: 18 | B21: IDMS-004 | C21: NISHITH SURENDRAN NATHAN KAVIL VADAKKE VEETIL SURENDRAN KUNIYIL | D21: 39083 | E21: 44197 | F21: 0 | G21: 0 | H21: 66 | I21: ='2013'!I12 -> 0 | J21: ='2014'!I15 -> 42 | K21: ='2015'!L16 -> 0 | L21: ='2016'!M17 -> 4 | N21: ='2018'!M17 -> 8 | O21: ='2019'!M15 -> 0 | P21: 0 | Q21: 0 | R21: 35 | S21: 12 | T21: 28 | U21: ='2025'!M16 -> 0 | W21: =SUM(P21:T21) -> 75 | X21: =W21/5 -> 15 | Y21: =SUM(30-X21)*AA21 -> 76.273973 | Z21: =AC21-E21 -> 1856 | AA21: =Z21/365 -> 5.0849315 | AB21: =SUM(AC21-D21)/365 -> 19.09589 | AC21: 46053
A22: 19 | B22: IDBS-024 | C22: ASLAMBHAI ARIFBHAI SHEIKH SHEIKH ARIFBHI MEHMOODBHAI | D22: 41334 | E22: 44197 | I22: ='2013'!I13 -> 0 | J22: ='2014'!I16 -> 0 | K22: ='2015'!L17 -> 0 | L22: ='2016'!M18 -> 37 | N22: ='2018'!M18 -> 7 | O22: ='2019'!M16 -> 0 | P22: 0 | Q22: 0 | R22: 11 | S22: 0 | T22: 19 | U22: ='2025'!M17 -> 0 | W22: =SUM(P22:T22) -> 30 | X22: =W22/5 -> 6 | Y22: =SUM(30-X22)*AA22 -> 122.03836 | Z22: =AC22-E22 -> 1856 | AA22: =Z22/365 -> 5.0849315 | AB22: =SUM(AC22-D22)/365 -> 12.928767 | AC22: 46053
A23: 20 | B23: IDBS-016 | C23: PRAVEEN KUMAR PERIYADAN KADINHIPALLY | D23: 40483 | E23: 44197 | F23: 0 | G23: 0 | H23: 40 | I23: ='2013'!I16 -> 44 | J23: ='2014'!I19 -> 23 | K23: ='2015'!L19 -> 50 | L23: ='2016'!M20 -> 38 | N23: ='2018'!M20 -> 47 | O23: ='2019'!M18 -> 49 | P23: 0 | Q23: 29 | R23: 20 | S23: 35 | T23: 28 | U23: ='2025'!M18 -> 0 | W23: =SUM(P23:T23) -> 112 | X23: =W23/5 -> 22.4 | Y23: =SUM(30-X23)*AA23 -> 42.414247 | Z23: =AC23-E23 -> 2037 | AA23: =Z23/365 -> 5.5808219 | AB23: =SUM(AC23-D23)/365 -> 15.756164 | AC23: 46234
A24: 21 | B24: IDMS-108 | C24: DEEPAK PUSHPAN PUSHPANGANGADHARAN | D24: 44652 | E24: 44682 | R24: 7 | S24: 16 | T24: 37 | U24: ='2025'!M19 -> 17 | W24: =SUM(P24:U24) -> 77 | X24: =W24/AA24 -> 20.499635 | Y24: =SUM(30-X24)*AA24 -> 35.684932 | Z24: =AC24-E24 -> 1371 | AA24: =Z24/365 -> 3.7561644 | AB24: =SUM(AC24-D24)/365 -> 3.8383562 | AC24: 46053
A25: 22 | B25: IDMS-109 | C25: JITHIN PANDIYATH RAJAN PANDIYATH RAMAN RAJAN | D25: 44652 | E25: 44652 | R25: 0 | S25: 0 | T25: 0 | U25: ='2025'!M20 -> 21 | W25: =SUM(P25:T25) -> 0 | X25: =W25/5 -> 0 | Y25: =SUM(30-X25)*AA25 -> 115.15068 | Z25: =AC25-E25 -> 1401 | AA25: =Z25/365 -> 3.8383562 | AB25: =SUM(AC25-D25)/365 -> 3.8383562 | AC25: 46053
A26: 23 | B26: IDMS-017 | C26: PRAMOD POINACHI KUNHI RAMAN POINACHI | D26: 44652 | E26: 44682 | R26: 0 | S26: 0 | T26: 26 | U26: ='2025'!M21 -> 0 | V26: ='2026'!M106 -> 1 | W26: =SUM(P26:V26) -> 27 | X26: =W26/5 -> 5.4 | Y26: =SUM(30-X26)*AA26 -> 92.401644 | Z26: =AC26-E26 -> 1371 | AA26: =Z26/365 -> 3.7561644 | AB26: =SUM(AC26-D26)/365 -> 3.8383562 | AC26: 46053
A27: 24 | B27: IDBM-023 | C27: PRABHAKAR PONNAM ANJAIAH PONNAM | D27: 41244 | E27: 44197 | F27: 41244 | H27: 0 | I27: ='2013'!I24 -> 0 | J27: ='2014'!I26 -> 0 | K27: ='2015'!L25 -> 0 | L27: ='2016'!M27 -> 0 | N27: ='2018'!M25 -> 47 | O27: ='2019'!M22 -> 86 | P27: 0 | Q27: 58 | R27: 45 | S27: 46 | T27: 0 | U27: ='2025'!M22 -> 46 | W27: =SUM(P27:T27) -> 149 | X27: =W27/5 -> 29.8 | Y27: =SUM(30-X27)*AA27 -> 1.0169863 | Z27: =AC27-E27 -> 1856 | AA27: =Z27/365 -> 5.0849315 | AB27: =SUM(AC27-D27)/365 -> 13.175342 | AC27: 46053
A28: 25 | B28: IDMM-034 | C28: GANGARAJAM BAKKAIAH ODNALA | D28: 41913 | E28: 44197 | J28: 0 | K28: ='2015'!L43 -> 0 | L28: ='2016'!M38 -> 0 | N28: ='2018'!M35 -> 0 | O28: ='2019'!M30 -> 78 | P28: 0 | Q28: 102 | R28: 0 | S28: 57 | T28: 41 | U28: ='2025'!M23 -> 9 | W28: =SUM(P28:T28) -> 200 | X28: =W28/5 -> 40 | Y28: =SUM(30-X28)*AA28 -> -50.849315 | Z28: =AC28-E28 -> 1856 | AA28: =Z28/365 -> 5.0849315 | AB28: =SUM(AC28-D28)/365 -> 11.342466 | AC28: 46053
A29: 26 | B29: IDMM-028 | C29: MOHAMMED JABID MOIDU KUNHI | D29: 41760 | E29: 44197 | J29: ='2014'!I44 -> 0 | K29: ='2015'!L38 -> 48 | L29: ='2016'!M47 -> 22 | N29: ='2018'!M43 -> 0 | O29: ='2019'!M36 -> 62 | P29: 0 | Q29: 61 | R29: 0 | S29: 61 | T29: 0 | U29: ='2025'!M24 -> 8 | W29: =SUM(Q29:U29) -> 130 | X29: =W29/5 -> 26 | Y29: =SUM(30-X29)*AA29 -> 20.339726 | Z29: =AC29-E29 -> 1856 | AA29: =Z29/365 -> 5.0849315 | AB29: =SUM(AC29-D29)/365 -> 11.761644 | AC29: 46053
A30: 27 | B30: IDMM-021 | C30: ARUN KANNOTHIL MANIKANDAN KANNOTHIL | D30: 40878 | E30: 44197 | F30: 0 | H30: 0 | J30: ='2014'!I66 -> 81 | K30: ='2015'!L69 -> 0 | L30: ='2016'!M49 -> 0 | N30: ='2018'!M45 -> 0 | O30: ='2019'!M38 -> 31 | P30: 21 | Q30: 0 | R30: 61 | S30: 0 | T30: 62 | U30: ='2025'!M25 -> 0 | W30: =SUM(P30:T30) -> 144 | X30: =W30/5 -> 28.8 | Y30: =SUM(30-X30)*AA30 -> 6.1019178 | Z30: =AC30-E30 -> 1856 | AA30: =Z30/365 -> 5.0849315 | AB30: =SUM(AC30-D30)/365 -> 14.178082 | AC30: 46053
A31: 28 | B31: IDBM-040 | C31: PARAMESH CHANDRAIAH NASPURI CHANDRAIAH POSANNA NASPURI | D31: 42522 | E31: 44197 | F31: JOIN IN 2016 | L31: ='2016'!M51 -> 0 | N31: ='2018'!M47 -> 0 | O31: ='2019'!M40 -> 63 | P31: 40 | Q31: 23 | R31: 0 | S31: 31 | T31: 0 | U31: ='2025'!M26 -> 81 | W31: =SUM(P31:T31) -> 94 | X31: =W31/5 -> 18.8 | Y31: =SUM(30-X31)*AA31 -> 56.951233 | Z31: =AC31-E31 -> 1856 | AA31: =Z31/365 -> 5.0849315 | AB31: =SUM(AC31-D31)/365 -> 9.6739726 | AC31: 46053
A32: 29 | B32: IDBM-043 | C32: MUHAMMAD SABIR MUHAMMAD SAEED | D32: 42675 | E32: 44197 | L32: ='2016'!M57 -> 0 | N32: ='2018'!M51 -> 21 | O32: ='2019'!M43 -> 50 | P32: 0 | Q32: 131 | R32: 0 | S32: 0 | T32: 63 | U32: ='2025'!M27 -> 41 | W32: =SUM(Q32:U32) -> 235 | X32: =W32/5 -> 47 | Y32: =SUM(30-X32)*AA32 -> -86.443836 | Z32: =AC32-E32 -> 1856 | AA32: =Z32/365 -> 5.0849315 | AB32: =SUM(AC32-D32)/365 -> 9.2547945 | AC32: 46053
A33: 30 | B33: IDBM-048 | C33: SUNIL KUMAR RAM JIVAN | D33: 42948 | E33: 44197 | N33: ='2018'!M59 -> 0 | O33: ='2019'!M50 -> 61 | P33: 0 | Q33: 30 | R33: 30 | S33: 0 | T33: 78 | U33: ='2025'!M28 -> 0 | W33: =SUM(P33:T33) -> 138 | X33: =W33/5 -> 27.6 | Y33: =SUM(30-X33)*AA33 -> 12.203836 | Z33: =AC33-E33 -> 1856 | AA33: =Z33/365 -> 5.0849315 | AB33: =SUM(AC33-D33)/365 -> 8.5068493 | AC33: 46053
A34: 31 | B34: IDMM-050 | C34: AKASH RAVINDRA TAMBEKAR RAVINDRA PANDURAG TAMBEKAR | D34: 42979 | E34: 44197 | N34: ='2018'!M62 -> 0 | O34: ='2019'!M53 -> 31 | P34: 0 | Q34: 0 | R34: 63 | S34: 34 | T34: 40 | U34: ='2025'!M29 -> 32 | W34: =SUM(P34:T34) -> 137 | X34: =W34/5 -> 27.4 | Y34: =SUM(30-X34)*AA34 -> 13.220822 | Z34: =AC34-E34 -> 1856 | AA34: =Z34/365 -> 5.0849315 | AB34: =SUM(AC34-D34)/365 -> 8.4219178 | AC34: 46053
A35: 32 | B35: IDMM-053 | C35: THIRUPATHI JAINAPURAPU BHEEMAIAH JAINAPURAPU | D35: 43101 | E35: 44197 | N35: ='2018'!M64 -> 0 | O35: ='2019'!M55 -> 24 | P35: 0 | Q35: 0 | R35: 46 | S35: 28 | T35: 34 | U35: ='2025'!M30 -> 0 | W35: =SUM(P35:T35) -> 108 | X35: =W35/5 -> 21.6 | Y35: =SUM(30-X35)*AA35 -> 42.713425 | Z35: =AC35-E35 -> 1856 | AA35: =Z35/365 -> 5.0849315 | AB35: =SUM(AC35-D35)/365 -> 8.0876712 | AC35: 46053
A36: 33 | B36: IDMM-010 | C36: SAI KUMAR EDUGUNURI NADAIAH EDUGUNURI | D36: 43101 | E36: 44197 | N36: ='2018'!M65 -> 0 | O36: ='2019'!M56 -> 0 | P36: 165 | Q36: 0 | R36: 77 | S36: 0 | T36: 50 | U36: ='2025'!M31 -> 0 | W36: =SUM(Q36:T36) -> 127 | X36: =W36/5 -> 25.4 | Y36: =SUM(30-X36)*AA36 -> 23.390685 | Z36: =AC36-E36 -> 1856 | AA36: =Z36/365 -> 5.0849315 | AB36: =SUM(AC36-D36)/365 -> 8.0876712 | AC36: 46053
A37: 34 | B37: IDMM-054 | C37: MOHAMMED TAHIR KHAN PATHAN | D37: 43132 | E37: 44197 | N37: ='2018'!M66 -> 0 | O37: ='2019'!M57 -> 0 | P37: 0 | Q37: 24 | R37: 64 | S37: 0 | T37: 62 | U37: ='2025'!M32 -> 0 | W37: =SUM(P37:T37) -> 150 | X37: =W37/5 -> 30 | Y37: =SUM(30-X37)*AA37 -> 0 | Z37: =AC37-E37 -> 1856 | AA37: =Z37/365 -> 5.0849315 | AB37: =SUM(AC37-D37)/365 -> 8.0027397 | AC37: 46053
A38: 35 | B38: IDMM-055 | C38: GANESH KANAUJIA RAM CHANDAR KANAUJIA | D38: 43191 | E38: 44197 | N38: ='2018'!M67 -> 0 | O38: ='2019'!M58 -> 7 | P38: 97 | Q38: 0 | R38: 0 | S38: 63 | T38: 0 | U38: ='2025'!M33 -> 61 | W38: =SUM(P38:T38) -> 160 | X38: =W38/5 -> 32 | Y38: =SUM(30-X38)*AA38 -> -10.169863 | Z38: =AC38-E38 -> 1856 | AA38: =Z38/365 -> 5.0849315 | AB38: =SUM(AC38-D38)/365 -> 7.8410959 | AC38: 46053
A39: 36 | B39: IDMM-056 | C39: NOOH THANCHANKANDY MOIDEEN KUTTY KALLIAN KATTIL | D39: 43282 | E39: 44197 | N39: ='2018'!M69 -> 0 | O39: ='2019'!M60 -> 13 | P39: 27 | Q39: 55 | R39: 45 | S39: 51 | T39: 31 | U39: ='2025'!M34 -> 7 | W39: =SUM(Q39:U39) -> 189 | X39: =W39/5 -> 37.8 | Y39: =SUM(30-X39)*AA39 -> -39.662466 | Z39: =AC39-E39 -> 1856 | AA39: =Z39/365 -> 5.0849315 | AB39: =SUM(AC39-D39)/365 -> 7.5917808 | AC39: 46053
A40: 37 | B40: IDMM-058 | C40: KAREEM CHOKKIYAN MOIDEENKUTTY VALAPPIL | D40: 43466 | E40: 44197 | N40: 0 | O40: ='2019'!M63 -> 0 | P40: 0 | Q40: 27 | R40: 33 | S40: 0 | T40: 61 | U40: ='2025'!M35 -> 0 | W40: =SUM(P40:T40) -> 121 | X40: =W40/5 -> 24.2 | Y40: =SUM(30-X40)*AA40 -> 32.845479 | Z40: =AC40-E40 -> 2067 | AA40: =Z40/365 -> 5.6630137 | AB40: =SUM(AC40-D40)/365 -> 7.6657534 | AC40: 46264
...

Sheet 2026
A1: SI NO | B1: STAFF NAME | C1: JOINING DATE | D1: 1ST LEAVE | F1: 2ND LEAVE | H1: 3RD LEAVE | J1: 1 | K1: 2 | L1: 3 | M1: TOTAL | N1: Remarks
A2: 1 | B2: KANTESH GAGAN DAS NIHALACHANDANI | C2: 39295 | D2: 46056 | E2: 46058 | J2: =E2-D2 -> 2 | K2: =G2-F2 -> 0 | L2: =I2-H2 -> 0 | M2: =J2+K2+L2 -> 2
A3: 2 | B3: PAWAN JAIKISHIN KOTAI | C3: 41883 | D3: 46072 | E3: 46086 | J3: =E3-D3 -> 14 | K3: =G3-F3 -> 0 | L3: =I3-H3 -> 0 | M3: =J3+K3+L3 -> 14
A4: 3 | B4: SANDEEP PULLANCHIODAN RAMATH SURENDRAN KURINHERI | C4: 42740 | J4: =E4-D4 -> 0 | K4: =G4-F4 -> 0 | L4: =I4-H4 -> 0 | M4: =J4+K4+L4 -> 0
A5: 4 | B5: AMAL SID | C5: 44762 | D5: 46023 | E5: 46053 | J5: =E5-D5 -> 30 | K5: =G5-F5 -> 0 | L5: =I5-H5 -> 0 | M5: =J5+K5+L5 -> 30
A6: 5 | B6: Nainika Girish | C6: 45658 | J6: =E6-D6 -> 0 | K6: =G6-F6 -> 0 | L6: =I6-H6 -> 0 | M6: =J6+K6+L6 -> 0
A7: 6 | B7: ADARSH VERNEKAR | C7: 45301 | J7: =E7-D7 -> 0 | K7: =G7-F7 -> 0 | L7: =I7-H7 -> 0 | M7: =J7+K7+L7 -> 0
A8: 7 | B8: MELVIN THOMAS | C8: 45432 | D8: 46054 | E8: 46068 | J8: =E8-D8 -> 14 | K8: =G8-F8 -> 0 | L8: =I8-H8 -> 0 | M8: =J8+K8+L8 -> 14
A9: 8 | B9: SANJAY MICHUMAL PUNJABI | C9: 39083 | D9: 46077 | E9: 46084 | J9: =E9-D9 -> 7 | K9: =G9-F9 -> 0 | L9: =I9-H9 -> 0 | M9: =J9+K9+L9 -> 7
A10: 9 | B10: UMAIR RIAZ MUHAMMAD RIAZ SHOUQ | C10: 41852 | J10: =E10-D10 -> 0 | K10: =G10-F10 -> 0 | L10: =I10-H10 -> 0 | M10: =J10+K10+L10 -> 0
A11: 10 | B11: MAHESH CHAINANI RAMCHAND | C11: 39083 | J11: =E11-D11 -> 0 | K11: =G11-F11 -> 0 | L11: =I11-H11 -> 0 | M11: =J11+K11+L11 -> 0
A12: 11 | B12: JITESH CHAWLA | C12: 39083 | J12: =E12-D12 -> 0 | K12: =G12-F12 -> 0 | L12: =I12-H12 -> 0 | M12: =J12+K12+L12 -> 0
A13: 12 | B13: VIJAY KUMAR ASHOK KUMAR | C13: 39142 | J13: =E13-D13 -> 0 | K13: =G13-F13 -> 0 | L13: =I13-H13 -> 0 | M13: =J13+K13+L13 -> 0
A14: 13 | B14: ASHFAQ MUHAMMAD AHAMED | C14: 42036 | D14: 46072 | E14: 46086 | J14: =E14-D14 -> 14 | K14: =G14-F14 -> 0 | L14: =I14-H14 -> 0 | M14: =J14+K14+L14 -> 14
A15: 14 | B15: GAURAV NATHANI SANTOSH NATHANI | C15: 44317 | J15: =E15-D15 -> 0 | K15: =G15-F15 -> 0 | L15: =I15-H15 -> 0 | M15: =J15+K15+L15 -> 0
A16: 15 | B16: NISHITH SURENDRAN NATHAN KAVIL VADAKKE VEETIL SURENDRAN KUNIYIL | C16: 39083 | J16: =E16-D16 -> 0 | K16: =G16-F16 -> 0 | L16: =I16-H16 -> 0 | M16: =J16+K16+L16 -> 0
A17: 16 | B17: ASLAMBHAI ARIFBHAI SHEIKH SHEIKH ARIFBHI MEHMOODBHAI | C17: 41334 | J17: =E17-D17 -> 0 | K17: =G17-F17 -> 0 | L17: =I17-H17 -> 0 | M17: =J17+K17+L17 -> 0
A18: 17 | B18: PRAVEEN KUMAR PERIYADAN KADINHIPALLY | C18: 40483 | J18: =E18-D18 -> 0 | K18: =G18-F18 -> 0 | L18: =I18-H18 -> 0 | M18: =J18+K18+L18 -> 0
A19: 18 | B19: DEEPAK PUSHPAN PUSHPANGANGADHARAN | C19: 44652 | J19: =E19-D19 -> 0 | K19: =G19-F19 -> 0 | L19: =I19-H19 -> 0 | M19: =J19+K19+L19 -> 0
A20: 19 | B20: JITHIN PANDIYATH RAJAN PANDIYATH RAMAN RAJAN | C20: 44652 | J20: =E20-D20 -> 0 | K20: =G20-F20 -> 0 | L20: =I20-H20 -> 0 | M20: =J20+K20+L20 -> 0
A21: 20 | B21: PRAMOD POINACHI KUNHI RAMAN POINACHI | C21: 44652 | J21: =E21-D21 -> 0 | K21: =G21-F21 -> 0 | L21: =I21-H21 -> 0 | M21: =J21+K21+L21 -> 0
A22: 21 | B22: PRABHAKAR PONNAM ANJAIAH PONNAM | C22: 41244 | J22: =E22-D22 -> 0 | K22: =G22-F22 -> 0 | L22: =I22-H22 -> 0 | M22: =J22+K22+L22 -> 0
A23: 22 | B23: GANGARAJAM BAKKAIAH ODNALA | C23: 41913 | J23: =E23-D23 -> 0 | K23: =G23-F23 -> 0 | L23: =I23-H23 -> 0 | M23: =J23+K23+L23 -> 0
A24: 23 | B24: MOHAMMED JABID MOIDU KUNHI | C24: 41760 | J24: =E24-D24 -> 0 | K24: =G24-F24 -> 0 | L24: =I24-H24 -> 0 | M24: =J24+K24+L24 -> 0
A25: 24 | B25: ARUN KANNOTHIL MANIKANDAN KANNOTHIL | C25: 40878 | J25: =E25-D25 -> 0 | K25: =G25-F25 -> 0 | L25: =I25-H25 -> 0 | M25: =J25+K25+L25 -> 0
A26: 25 | B26: PARAMESH CHANDRAIAH NASPURI CHANDRAIAH POSANNA NASPURI | C26: 42522 | J26: =E26-D26 -> 0 | K26: =G26-F26 -> 0 | L26: =I26-H26 -> 0 | M26: =J26+K26+L26 -> 0
... A49: 48 | B49: MEHBOOB ALOM MOULANA ABUL KALAM | C49: 44409 | J49: =E49-D49 -> 0 | K49: =G49-F49 -> 0 | L49: =I49-H49 -> 0 | M49: =J49+K49+L49 -> 0
A50: 49 | B50: MOHAMMAD REAZ UDDIN MOHAMMAD DULAL MIA | C50: 44378 | D50: 46023 | E50: 46069 | J50: =E50-D50 -> 46 | K50: =G50-F50 -> 0 | L50: =I50-H50 -> 0 | M50: =J50+K50+L50 -> 46
A51: 50 | B51: FIRDUS ALOM TALUKDAR MOKTAR UDDIN TALUKDAR | C51: 44470 | J51: =E51-D51 -> 0 | K51: =G51-F51 -> 0 | L51: =I51-H51 -> 0 | M51: =J51+K51+L51 -> 0
A52: 51 | B52: BISWAJIT DEB BIKASH DEB | C52: 44470 | J52: =E52-D52 -> 0 | K52: =G52-F52 -> 0 | L52: =I52-H52 -> 0 | M52: =J52+K52+L52 -> 0
A53: 52 | B53: SHAMIL NISATH SULAIMAN SYED SULAIMAN | C53: 44470 | J53: =E53-D53 -> 0 | K53: =G53-F53 -> 0 | L53: =I53-H53 -> 0 | M53: =J53+K53+L53 -> 0
A54: 53 | B54: SUDHIR KUMAR SUBEDAR | C54: 44470 | J54: =E54-D54 -> 0 | K54: =G54-F54 -> 0 | L54: =I54-H54 -> 0 | M54: =J54+K54+L54 -> 0
A55: 54 | B55: AMIL TAJ MUHAMMAD TAJ | C55: 44607 | J55: =E55-D55 -> 0 | K55: =G55-F55 -> 0 | L55: =I55-H55 -> 0 | M55: =J55+K55+L55 -> 0
A56: 55 | B56: SABITH MANAPPATTU NOUSHAD NOUSHAD MANAPPATTU MAJEED | C56: 44593 | J56: =E56-D56 -> 0 | K56: =G56-F56 -> 0 | L56: =I56-H56 -> 0 | M56: =J56+K56+L56 -> 0
A57: 56 | B57: MD SUHAL AHMED MD TAFAZZUL ALI | C57: 44652 | J57: =E57-D57 -> 0 | K57: =G57-F57 -> 0 | L57: =I57-H57 -> 0 | M57: =J57+K57+L57 -> 0
A58: 57 | B58: MUHAMMED RASHEEQUE NEROM PARAMMAL MUHAMMAD LUKHMAN NEROM PARAMMAL | C58: 44652 | D58: 46030 | E58: 46053 | J58: =E58-D58 -> 23 | K58: =G58-F58 -> 0 | L58: =I58-H58 -> 0 | M58: =J58+K58+L58 -> 23
A59: 58 | B59: MOTIUR RAHMAN SOHID ULLAH | C59: 44652 | J59: =E59-D59 -> 0 | K59: =G59-F59 -> 0 | L59: =I59-H59 -> 0 | M59: =J59+K59+L59 -> 0
A60: 59 | B60: MD MONJURUL ISLAM MD OMAR FARUK | C60: 44652 | J60: =E60-D60 -> 0 | K60: =G60-F60 -> 0 | L60: =I60-H60 -> 0 | M60: =J60+K60+L60 -> 0
A61: 60 | B61: VIKASH KUMAR RAJENDRA KUMAR | C61: 44734 | J61: =E61-D61 -> 0 | K61: =G61-F61 -> 0 | L61: =I61-H61 -> 0 | M61: =J61+K61+L61 -> 0
A62: 61 | B62: SADIK ALOM IMAN UDDIN | C62: 44682 | J62: 0 | K62: =G62-F62 -> 0 | L62: =I62-H62 -> 0 | M62: 0
...

Sheet 2025
A1: SI NO | B1: STAFF NAME | C1: JOINING DATE | D1: 1ST LEAVE | F1: 2ND LEAVE | H1: 3RD LEAVE | J1: 1 | K1: 2 | L1: 3 | M1: TOTAL | N1: Remarks
A2: 1 | B2: KANTESH GAGAN DAS NIHALACHANDANI | C2: 39295 | D2: 45699 | E2: 45704 | F2: 45865 | G2: 45886 | J2: =E2-D2 -> 5 | K2: =G2-F2 -> 21 | L2: =I2-H2 -> 0 | M2: =J2+K2+L2 -> 26
A3: 2 | B3: PAWAN JAIKISHIN KOTAI | C3: 41883 | D3: 45778 | E3: 45802 | J3: =E3-D3 -> 24 | K3: =G3-F3 -> 0 | L3: =I3-H3 -> 0 | M3: =J3+K3+L3 -> 24
A4: 3 | B4: SANDEEP PULLANCHIODAN RAMATH SURENDRAN KURINHERI | C4: 42740 | D4: 45708 | E4: 45718 | J4: =E4-D4 -> 10 | K4: =G4-F4 -> 0 | L4: =I4-H4 -> 0 | M4: =J4+K4+L4 -> 10
A5: 4 | B5: AMAL SID | C5: 44762 | D5: 46016 | E5: 46022 | J5: =E5-D5 -> 6 | K5: =G5-F5 -> 0 | L5: =I5-H5 -> 0 | M5: =J5+K5+L5 -> 6
A6: 5 | B6: Nainika Girish | C6: 45658 | J6: =E6-D6 -> 0 | K6: =G6-F6 -> 0 | L6: =I6-H6 -> 0 | M6: =J6+K6+L6 -> 0
A7: 6 | B7: ADARSH VERNEKAR | C7: 45301 | D7: 45927 | E7: 45955 | J7: =E7-D7 -> 28 | K7: =G7-F7 -> 0 | L7: =I7-H7 -> 0 | M7: =J7+K7+L7 -> 28
A8: 7 | B8: MELVIN THOMAS | C8: 45432 | J8: =E8-D8 -> 0 | K8: =G8-F8 -> 0 | L8: =I8-H8 -> 0 | M8: =J8+K8+L8 -> 0
A9: 8 | B9: SANJAY MICHUMAL PUNJABI | C9: 39083 | J9: =E9-D9 -> 0 | K9: =G9-F9 -> 0 | L9: =I9-H9 -> 0 | M9: =J9+K9+L9 -> 0
A10: 9 | B10: UMAIR RIAZ MUHAMMAD RIAZ SHOUQ | C10: 41852 | J10: =E10-D10 -> 0 | K10: =G10-F10 -> 0 | L10: =I10-H10 -> 0 | M10: =J10+K10+L10 -> 0
A11: 10 | B11: MAHESH CHAINANI RAMCHAND | C11: 39083 | D11: 45658 | E11: 45659 | F11: 45834 | G11: 45848 | J11: =E11-D11 -> 1 | K11: =G11-F11 -> 14 | L11: =I11-H11 -> 0 | M11: =J11+K11+L11 -> 15
A12: 11 | B12: JITESH CHAWLA | C12: 39083 | D12: 45853 | E12: 45861 | F12: 45897 | G12: 45909 | J12: =E12-D12 -> 8 | K12: =G12-F12 -> 12 | L12: =I12-H12 -> 0 | M12: =J12+K12+L12 -> 20
A13: 12 | B13: VIJAY KUMAR ASHOK KUMAR | C13: 39142 | D13: 45975 | E13: 45979 | J13: =E13-D13 -> 4 | K13: =G13-F13 -> 0 | L13: =I13-H13 -> 0 | M13: =J13+K13+L13 -> 4
A14: 13 | B14: ASHFAQ MUHAMMAD AHAMED | C14: 42036 | J14: =E14-D14 -> 0 | K14: =G14-F14 -> 0 | L14: =I14-H14 -> 0 | M14: =J14+K14+L14 -> 0
A15: 14 | B15: GAURAV NATHANI SANTOSH NATHANI | C15: 44317 | J15: =E15-D15 -> 0 | K15: =G15-F15 -> 0 | L15: =I15-H15 -> 0 | M15: =J15+K15+L15 -> 0
A16: 15 | B16: NISHITH SURENDRAN NATHAN KAVIL VADAKKE VEETIL SURENDRAN KUNIYIL | C16: 39083 | J16: =E16-D16 -> 0 | K16: =G16-F16 -> 0 | L16: =I16-H16 -> 0 | M16: =J16+K16+L16 -> 0
A17: 16 | B17: ASLAMBHAI ARIFBHAI SHEIKH SHEIKH ARIFBHI MEHMOODBHAI | C17: 41334 | J17: =E17-D17 -> 0 | K17: =G17-F17 -> 0 | L17: =I17-H17 -> 0 | M17: =J17+K17+L17 -> 0
A18: 17 | B18: PRAVEEN KUMAR PERIYADAN KADINHIPALLY | C18: 40483 | J18: =E18-D18 -> 0 | K18: =G18-F18 -> 0 | L18: =I18-H18 -> 0 | M18: =J18+K18+L18 -> 0
A19: 18 | B19: DEEPAK PUSHPAN PUSHPANGANGADHARAN | C19: 44652 | D19: 45673 | E19: 45690 | J19: =E19-D19 -> 17 | K19: =G19-F19 -> 0 | L19: =I19-H19 -> 0 | M19: =J19+K19+L19 -> 17
A20: 19 | B20: JITHIN PANDIYATH RAJAN PANDIYATH RAMAN RAJAN | C20: 44652 | D20: 45756 | E20: 45777 | J20: =E20-D20 -> 21 | K20: =G20-F20 -> 0 | L20: =I20-H20 -> 0 | M20: =J20+K20+L20 -> 21
A21: 20 | B21: PRAMOD POINACHI KUNHI RAMAN POINACHI | C21: 44652 | J21: =E21-D21 -> 0 | K21: =G21-F21 -> 0 | L21: =I21-H21 -> 0 | M21: =J21+K21+L21 -> 0
A22: 21 | B22: PRABHAKAR PONNAM ANJAIAH PONNAM | C22: 41244 | D22: 45780 | E22: 45826 | J22: =E22-D22 -> 46 | K22: =G22-F22 -> 0 | L22: =I22-H22 -> 0 | M22: =J22+K22+L22 -> 46
A23: 22 | B23: GANGARAJAM BAKKAIAH ODNALA | C23: 41913 | D23: 45761 | E23: 45770 | J23: =E23-D23 -> 9 | K23: =G23-F23 -> 0 | L23: =I23-H23 -> 0 | M23: =J23+K23+L23 -> 9
A24: 23 | B24: MOHAMMED JABID MOIDU KUNHI | C24: 41760 | D24: 45680 | E24: 45688 | J24: =E24-D24 -> 8 | K24: =G24-F24 -> 0 | L24: =I24-H24 -> 0 | M24: =J24+K24+L24 -> 8
A25: 24 | B25: ARUN KANNOTHIL MANIKANDAN KANNOTHIL | C25: 40878 | J25: =E25-D25 -> 0 | K25: =G25-F25 -> 0 | L25: =I25-H25 -> 0 | M25: =J25+K25+L25 -> 0
A26: 25 | B26: PARAMESH CHANDRAIAH NASPURI CHANDRAIAH POSANNA NASPURI | C26: 42522 | D26: 45759 | E26: 45840 | J26: =E26-D26 -> 81 | K26: =G26-F26 -> 0 | L26: =I26-H26 -> 0 | M26: =J26+K26+L26 -> 81
A27: 26 | B27: MUHAMMAD SABIR MUHAMMAD SAEED | C27: 42675 | D27: 45798 | E27: 45839 | J27: =E27-D27 -> 41 | K27: =G27-F27 -> 0 | L27: =I27-H27 -> 0 | M27: =J27+K27+L27 -> 41
A28: 27 | B28: SUNIL KUMAR RAM JIVAN | C28: 42948 | J28: =E28-D28 -> 0 | K28: =G28-F28 -> 0 | L28: =I28-H28 -> 0 | M28: =J28+K28+L28 -> 0
A29: 28 | B29: AKASH RAVINDRA TAMBEKAR RAVINDRA PANDURAG TAMBEKAR | C29: 42979 | D29: 45785 | E29: 45817 | J29: =E29-D29 -> 32 | K29: =G29-F29 -> 0 | L29: =I29-H29 -> 0 | M29: =J29+K29+L29 -> 32
A30: 29 | B30: THIRUPATHI JAINAPURAPU BHEEMAIAH JAINAPURAPU | C30: 43101 | J30: =E30-D30 -> 0 | K30: =G30-F30 -> 0 | L30: =I30-H30 -> 0 | M30: =J30+K30+L30 -> 0
A31: 30 | B31: SAI KUMAR EDUGUNURI NADAIAH EDUGUNURI | C31: 43101 | J31: =E31-D31 -> 0 | K31: =G31-F31 -> 0 | L31: =I31-H31 -> 0 | M31: =J31+K31+L31 -> 0
A32: 31 | B32: MOHAMMED TAHIR KHAN PATHAN | C32: 43132 | J32: =E32-D32 -> 0 | K32: =G32-F32 -> 0 | L32: =I32-H32 -> 0 | M32: =J32+K32+L32 -> 0
A33: 32 | B33: GANESH KANAUJIA RAM CHANDAR KANAUJIA | C33: 43191 | D33: 45722 | E33: 45783 | J33: =E33-D33 -> 61 | K33: =G33-F33 -> 0 | L33: =I33-H33 -> 0 | M33: =J33+K33+L33 -> 61
A34: 33 | B34: NOOH THANCHANKANDY MOIDEEN KUTTY KALLIAN KATTIL | C34: 43282 | D34: 45946 | E34: 45953 | J34: =E34-D34 -> 7 | K34: =G34-F34 -> 0 | L34: =I34-H34 -> 0 | M34: =J34+K34+L34 -> 7
A35: 34 | B35: KAREEM CHOKKIYAN MOIDEENKUTTY VALAPPIL | C35: 43466 | J35: =E35-D35 -> 0 | K35: =G35-F35 -> 0 | L35: =I35-H35 -> 0 | M35: =J35+K35+L35 -> 0
A36: 35 | B36: MIDHUN VALIYAPURAKKAL MOHANAN MOHANAN VALIYAPURAKKAL VELAYUDHAN | C36: 43497 | J36: =E36-D36 -> 0 | K36: =G36-F36 -> 0 | L36: =I36-H36 -> 0 | M36: =J36+K36+L36 -> 0
A37: 36 | B37: ABU SALIH MAYYERI MOHAMMED KUTTY MAYYERI | C37: 43617 | J37: =E37-D37 -> 0 | K37: =G37-F37 -> 0 | L37: =I37-H37 -> 0 | M37: =J37+K37+L37 -> 0
A38: 37 | B38: MUHAMMAD ABID MUHAMMAD SAEED | C38: 43617 | D38: 45749 | E38: 45767 | J38: =E38-D38 -> 18 | K38: =G38-F38 -> 0 | L38: =I38-H38 -> 0 | M38: =J38+K38+L38 -> 18
A39: 38 | B39: ATHUL ELLIKANDAVIDA KRISHNAN ALLIKANDAVIDA | C39: 43617 | J39: =E39-D39 -> 0 | K39: =G39-F39 -> 0 | L39: =I39-H39 -> 0 | M39: =J39+K39+L39 -> 0
A40: 39 | B40: VAMSHI VADNALA GANGADHAR VADNALA | C40: 43739 | D40: 45658 | E40: 45717 | J40: =E40-D40 -> 59 | K40: =G40-F40 -> 0 | L40: =I40-H40 -> 0 | M40: =J40+K40+L40 -> 59
...

Sheet 2024
A1: SI NO | B1: STAFF NAME | C1: JOINING DATE | D1: 1ST LEAVE | F1: 2ND LEAVE | H1: 3RD LEAVE | J1: 1 | K1: 2 | L1: 3 | M1: TOTAL | N1: Remarks
A2: IDFO-000 | B2: KANTESH GAGAN DAS NIHALACHANDANI | C2: 39295 | J2: =E2-D2 -> 0 | K2: =G2-F2 -> 0 | L2: =I2-H2 -> 0 | M2: =J2+K2+L2 -> 0
A3: IDMO-032 | B3: PAWAN JAIKISHIN KOTAI | C3: 41883 | D3: 45412 | E3: 45436 | J3: =E3-D3 -> 24 | K3: =G3-F3 -> 0 | L3: =I3-H3 -> 0 | M3: =J3+K3+L3 -> 24
A4: IDMO-044 | B4: SANDEEP PULLANCHIODAN RAMATH SURENDRAN KURINHERI | C4: 42736 | J4: =E4-D4 -> 0 | K4: =G4-F4 -> 0 | L4: =I4-H4 -> 0 | M4: =J4+K4+L4 -> 0
A5: IDBO-018 | B5: ABIRAL ARUN THAPA | C5: 40695 | J5: =E5-D5 -> 0 | K5: =G5-F5 -> 0 | L5: =I5-H5 -> 0 | M5: =J5+K5+L5 -> 0
A6: IDMO-090 | B6: GAURAV NATHANI SANTOSH NATHANI | C6: 44317 | D6: 45292 | E6: 45318 | J6: =E6-D6 -> 26 | K6: =G6-F6 -> 0 | L6: =I6-H6 -> 0 | M6: =J6+K6+L6 -> 26
A7: IDMO-101 | B7: RANJITH KUMAR NAMPELLY RAJAIAH | C7: 44501 | J7: =E7-D7 -> 0 | K7: =G7-F7 -> 0 | L7: =I7-H7 -> 0 | M7: =J7+K7+L7 -> 0
A8: IDMO-123 | B8: JISHNU JOHNY SHEEBA JOHNY VISWAMBARAN | C8: 44317 | J8: =E8-D8 -> 0 | K8: =G8-F8 -> 0 | L8: =I8-H8 -> 0 | M8: =J8+K8+L8 -> 0
A9: IDMS-001 | B9: SANJAY MICHUMAL PUNJABI | C9: 39083 | D9: 45492 | E9: 45497 | F9: 45511 | G9: 45514 | J9: =E9-D9 -> 5 | K9: =G9-F9 -> 3 | L9: =I9-H9 -> 0 | M9: =J9+K9+L9 -> 8
A10: IDMO-002 | B10: MAHESH CHAINANI RAMCHAND | C10: 39083 | D10: 45329 | E10: 45341 | F10: 45645 | G10: 45657 | J10: =E10-D10 -> 12 | K10: =G10-F10 -> 12 | L10: =I10-H10 -> 0 | M10: =J10+K10+L10 -> 24
A11: IDMS-003 | B11: JITESH CHAWLA | C11: 39083 | D11: 45467 | E11: 45472 | F11: 45505 | G11: 45515 | J11: =E11-D11 -> 5 | K11: =G11-F11 -> 10 | L11: =I11-H11 -> 0 | M11: =J11+K11+L11 -> 15
A12: IDBS-012 | B12: VIJAY KUMAR ASHOK KUMAR | C12: 39142 | D12: 45510 | E12: 45512 | J12: =E12-D12 -> 2 | K12: =G12-F12 -> 0 | L12: =I12-H12 -> 0 | M12: =J12+K12+L12 -> 2
A13: IDBO-036 | B13: ASHFAQ MUHAMMAD AHAMED | C13: 42036 | D13: 45495 | E13: 45508 | J13: =E13-D13 -> 13 | K13: =G13-F13 -> 0 | L13: =I13-H13 -> 0 | M13: =J13+K13+L13 -> 13
A14: IDMS-004 | B14: NISHITH SURENDRAN NATHAN KAVIL VADAKKE VEETIL SURENDRAN KUNIYIL | C14: 39083 | D14: 45508 | E14: 45536 | J14: =E14-D14 -> 28 | K14: =G14-F14 -> 0 | L14: =I14-H14 -> 0 | M14: =J14+K14+L14 -> 28
A15: IDBS-024 | B15: ASLAMBHAI ARIFBHAI SHEIKH SHEIKH ARIFBHI MEHMOODBHAI | C15: 41334 | D15: 45516 | E15: 45535 | J15: =E15-D15 -> 19 | K15: =G15-F15 -> 0 | L15: =I15-H15 -> 0 | M15: =J15+K15+L15 -> 19
A16: IDBS-016 | B16: PRAVEEN KUMAR PERIYADAN KADINHIPALLY | C16: 40483 | D16: 45624 | E16: 45652 | J16: =E16-D16 -> 28 | K16: =G16-F16 -> 0 | L16: =I16-H16 -> 0 | M16: =J16+K16+L16 -> 28
A17: IDMS-108 | B17: DEEPAK PUSHPAN PUSHPANGANGADHARAN | C17: 44652 | D17: 45380 | E17: 45417 | J17: =E17-D17 -> 37 | K17: =G17-F17 -> 0 | L17: =I17-H17 -> 0 | M17: =J17+K17+L17 -> 37
A18: IDMS-109 | B18: JITHIN PANDIYATH RAJAN PANDIYATH RAMAN RAJAN | C18: 44652 | J18: =E18-D18 -> 0 | K18: =G18-F18 -> 0 | L18: =I18-H18 -> 0 | M18: =J18+K18+L18 -> 0
A19: IDMS-017 | B19: PRAMOD POINACHI KUNHI RAMAN POINACHI | C19: 44652 | D19: 45478 | E19: 45504 | J19: =E19-D19 -> 26 | K19: =G19-F19 -> 0 | L19: =I19-H19 -> 0 | M19: =J19+K19+L19 -> 26
A20: IDBM-023 | B20: PRABHAKAR PONNAM ANJAIAH PONNAM | C20: 41244 | J20: =E20-D20 -> 0 | K20: =G20-F20 -> 0 | L20: =I20-H20 -> 0 | M20: =J20+K20+L20 -> 0
A21: IDBM-026 | B21: MUHAMMAD NIYAS KURIYAKATH MULLAVAPPIL NAZER | C21: 41518 | J21: =E21-D21 -> 0 | K21: =G21-F21 -> 0 | L21: =I21-H21 -> 0 | M21: =J21+K21+L21 -> 0
A22: IDBM-033 | B22: KABEER MULLAPURATH CHIRAPURATH | C22: 41883 | J22: =E22-D22 -> 0 | K22: =G22-F22 -> 0 | L22: =I22-H22 -> 0 | M22: =J22+K22+L22 -> 0
A23: IDMM-034 | B23: GANGARAJAM BAKKAIAH ODNALA | C23: 41913 | D23: 45305 | E23: 45326 | F23: 45558 | G23: 45578 | J23: =E23-D23 -> 21 | K23: =G23-F23 -> 20 | L23: =I23-H23 -> 0 | M23: =J23+K23+L23 -> 41
A24: IDBM-035 | B24: SHIJU VARAKKOTH KUNHIKANNAN NAMBIAR PEEDIKA VALAPPIL | C24: 42005 | J24: =E24-D24 -> 0 | K24: =G24-F24 -> 0 | L24: =I24-H24 -> 0 | M24: =J24+K24+L24 -> 0
A25: IDMM-028 | B25: MOHAMMED JABID MOIDU KUNHI | C25: 41760 | J25: =E25-D25 -> 0 | K25: =G25-F25 -> 0 | L25: =I25-H25 -> 0 | M25: =J25+K25+L25 -> 0
A26: IDBM-029 | B26: SUBHADIN CHUNNUM TAMANG TAMANG | C26: 41760 | J26: =E26-D26 -> 0 | K26: =G26-F26 -> 0 | L26: =I26-H26 -> 0 | M26: =J26+K26+L26 -> 0
A27: IDMM-021 | B27: ARUN KANNOTHIL MANIKANDAN KANNOTHIL | C27: 40878 | D27: 45416 | E27: 45478 | J27: =E27-D27 -> 62 | K27: =G27-F27 -> 0 | L27: =I27-H27 -> 0 | M27: =J27+K27+L27 -> 62
A28: IDBM-039 | B28: BIPLAB DEB AJIT DEB | C28: 42430 | J28: =E28-D28 -> 0 | K28: =G28-F28 -> 0 | L28: =I28-H28 -> 0 | M28: =J28+K28+L28 -> 0
A29: IDBM-040 | B29: PARAMESH CHANDRAIAH NASPURI CHANDRAIAH POSANNA NASPURI | C29: 42522 | J29: =E29-D29 -> 0 | K29: =G29-F29 -> 0 | L29: =I29-H29 -> 0 | M29: =J29+K29+L29 -> 0
A30: IDMM-041 | B30: MUHAMMAD USMAN RIAZ AHMAD | C30: 42614 | J30: =E30-D30 -> 0 | K30: =G30-F30 -> 0 | L30: =I30-H30 -> 0 | M30: =J30+K30+L30 -> 0
A31: IDMM-042 | B31: IMRAN KHAN MUBARAK MOHAMMED KHASIM | C31: 42644 | J31: =E31-D31 -> 0 | K31: =G31-F31 -> 0 | L31: =I31-H31 -> 0 | M31: =J31+K31+L31 -> 0
A32: IDBM-043 | B32: MUHAMMAD SABIR MUHAMMAD SAEED | C32: 42675 | D32: 45310 | E32: 45373 | J32: =E32-D32 -> 63 | K32: =G32-F32 -> 0 | L32: =I32-H32 -> 0 | M32: =J32+K32+L32 -> 63
A33: IDMC-047 | B33: SUNIL GOPALAN KOLOTHODY | C33: 42948 | J33: =E33-D33 -> 0 | K33: =G33-F33 -> 0 | L33: =I33-H33 -> 0 | M33: =J33+K33+L33 -> 0
A34: IDMM-049 | B34: UMESH RAMA NAIK RAMA NAIK | C34: 42948 | J34: =E34-D34 -> 0 | K34: =G34-F34 -> 0 | L34: =I34-H34 -> 0 | M34: =J34+K34+L34 -> 0
A35: IDMM-050 | B35: AKASH RAVINDRA TAMBEKAR | C35: 42979 | D35: 45396 | E35: 45436 | J35: =E35-D35 -> 40 | K35: =G35-F35 -> 0 | L35: =I35-H35 -> 0 | M35: =J35+K35+L35 -> 40
A36: IDMM-053 | B36: THIRUPATHI JAINAPURAPU BHEEMAIAH JAINAPURAPU | C36: 43101 | D36: 45566 | E36: 45600 | J36: =E36-D36 -> 34 | K36: =G36-F36 -> 0 | L36: =I36-H36 -> 0 | M36: =J36+K36+L36 -> 34
A37: IDMM-010 | B37: SAI KUMAR EDUGUNURI NADAIAH EDUGUNURI | C37: 43101 | D37: 45507 | E37: 45557 | J37: =E37-D37 -> 50 | K37: =G37-F37 -> 0 | L37: =I37-H37 -> 0 | M37: =J37+K37+L37 -> 50
A38: IDMM-054 | B38: MOHAMMED TAHIR KHAN PATHAN | C38: 43132 | D38: 45562 | E38: 45624 | J38: =E38-D38 -> 62 | K38: =G38-F38 -> 0 | L38: =I38-H38 -> 0 | M38: =J38+K38+L38 -> 62
A39: IDMM-055 | B39: GANESH KANAUJIA RAM CHANDAR KANAUJIA | C39: 43191 | J39: =E39-D39 -> 0 | K39: =G39-F39 -> 0 | L39: =I39-H39 -> 0 | M39: =J39+K39+L39 -> 0
A40: IDMM-057 | B40: ZESHAN ASLAM MUHAMMAD ASLAM | C40: 43282 | J40: =E40-D40 -> 0 | K40: =G40-F40 -> 0 | L40: =I40-H40 -> 0 | M40: =J40+K40+L40 -> 0
...

Sheet 2023
A1: SI NO | B1: STAFF NAME | C1: JOINING DATE | D1: 1ST LEAVE | F1: 2ND LEAVE | H1: 3RD LEAVE | J1: 3RD LEAVE | L1: 1 | M1: 2 | N1: 3 | O1: 4 | P1: TOTAL | Q1: Remarks
A2: IDFO-000 | B2: KANTESH GAGAN DAS NIHALACHANDANI | C2: 39295 | D2: 45137 | E2: 45161 | F2: 45176 | G2: 45188 | L2: =E2-D2 -> 24 | M2: =G2-F2 -> 12 | N2: =I2-H2 -> 0 | O2: =J2-I2 -> 0 | P2: =L2+M2+N2 -> 36
A3: IDMO-032 | B3: PAWAN JAIKISHIN KOTAI | C3: 41883 | D3: 45025 | E3: 45046 | L3: =E3-D3 -> 21 | M3: =G3-F3 -> 0 | N3: =I3-H3 -> 0 | O3: =J3-I3 -> 0 | P3: =L3+M3+N3 -> 21
A4: IDMO-044 | B4: SANDEEP PULLANCHIODAN RAMATH SURENDRAN KURINHERI | C4: 42736 | L4: =E4-D4 -> 0 | M4: =G4-F4 -> 0 | N4: =I4-H4 -> 0 | O4: =J4-I4 -> 0 | P4: =L4+M4+N4 -> 0
A5: IDBO-018 | B5: ABIRAL ARUN THAPA | C5: 40695 | L5: =E5-D5 -> 0 | M5: =G5-F5 -> 0 | N5: =I5-H5 -> 0 | O5: =J5-I5 -> 0 | P5: =L5+M5+N5 -> 0
A6: IDMO-090 | B6: GAURAV NATHANI SANTOSH NATHANI | C6: 44317 | D6: 45285 | E6: 45291 | L6: =E6-D6 -> 6 | M6: =G6-F6 -> 0 | N6: =I6-H6 -> 0 | O6: =J6-I6 -> 0 | P6: =L6+M6+N6 -> 6
A7: IDMO-101 | B7: RANJITH KUMAR NAMPELLY RAJAIAH | C7: 44501 | L7: =E7-D7 -> 0 | M7: =G7-F7 -> 0 | N7: =I7-H7 -> 0 | O7: =J7-I7 -> 0 | P7: =L7+M7+N7 -> 0
A8: IDMO-123 | B8: JISHNU JOHNY SHEEBA JOHNY VISWAMBARAN | C8: 44317 | D8: 45170 | E8: 45180 | L8: =E8-D8 -> 10 | M8: =G8-F8 -> 0 | N8: =I8-H8 -> 0 | O8: =J8-I8 -> 0 | P8: =L8+M8+N8 -> 10
A9: IDMS-001 | B9: SANJAY MICHUMAL PUNJABI | C9: 39083 | D9: 45004 | E9: 45011 | F9: 45104 | G9: 45110 | H9: 45272 | I9: 45275 | L9: =E9-D9 -> 7 | M9: =G9-F9 -> 6 | N9: =I9-H9 -> 3 | P9: =L9+M9+N9 -> 16
A10: IDMO-002 | B10: MAHESH CHAINANI RAMCHAND | C10: 39083 | D10: 45023 | E10: 45026 | F10: 45120 | G10: 45136 | L10: =E10-D10 -> 3 | M10: =G10-F10 -> 16 | N10: =I10-H10 -> 0 | O10: =J10-I10 -> 0 | P10: =L10+M10+N10 -> 19
A11: IDMS-003 | B11: JITESH CHAWLA | C11: 39083 | D11: 45110 | E11: 45118 | F11: 45168 | G11: 45182 | L11: =E11-D11 -> 8 | M11: =G11-F11 -> 14 | N11: =I11-H11 -> 0 | O11: =J11-I11 -> 0 | P11: =L11+M11+N11 -> 22
A12: IDBS-012 | B12: VIJAY KUMAR ASHOK KUMAR | C12: 39142 | D12: 44976 | E12: 44983 | F12: 45214 | G12: 45222 | H12: 45257 | I12: 45264 | J12: 45266 | K12: 45281 | L12: =E12-D12 -> 7 | M12: =G12-F12 -> 8 | N12: =I12-H12 -> 7 | O12: =K12-J12 -> 15 | P12: =L12+M12+N12+O12 -> 37
A13: IDBO-036 | B13: ASHFAQ MUHAMMAD AHAMED | C13: 42036 | D13: 45266 | E13: 45271 | L13: =E13-D13 -> 5 | M13: =G13-F13 -> 0 | N13: =I13-H13 -> 0 | O13: =J13-I13 -> 0 | P13: =L13+M13+N13 -> 5
A14: IDBO-036 | B14: PRAVEEN KUMAR KESHWANI | C14: 42036 | D14: 45102 | E14: 45109 | L14: =E14-D14 -> 7 | M14: =G14-F14 -> 0 | N14: =I14-H14 -> 0 | O14: =J14-I14 -> 0 | P14: =L14+M14+N14 -> 7
A15: IDMS-004 | B15: NISHITH SURENDRAN NATHAN KAVIL VADAKKE VEETIL SURENDRAN KUNIYIL | C15: 39083 | D15: 45242 | E15: 45254 | L15: =E15-D15 -> 12 | M15: =G15-F15 -> 0 | N15: =I15-H15 -> 0 | O15: =J15-I15 -> 0 | P15: =L15+M15+N15 -> 12
A16: IDBS-024 | B16: ASLAMBHAI ARIFBHAI SHEIKH SHEIKH ARIFBHI MEHMOODBHAI | C16: 41334 | L16: =E16-D16 -> 0 | M16: =G16-F16 -> 0 | N16: =I16-H16 -> 0 | O16: =J16-I16 -> 0 | P16: =L16+M16+N16 -> 0
A17: IDBS-016 | B17: PRAVEEN KUMAR PERIYADAN KADINHIPALLY | C17: 40483 | D17: 45138 | E17: 45173 | L17: =E17-D17 -> 35 | M17: =G17-F17 -> 0 | N17: =I17-H17 -> 0 | O17: =J17-I17 -> 0 | P17: =L17+M17+N17 -> 35
A18: IDMS-108 | B18: DEEPAK PUSHPAN PUSHPANGANGADHARAN | C18: 44652 | D18: 44927 | E18: 44943 | L18: =E18-D18 -> 16 | M18: =G18-F18 -> 0 | N18: =I18-H18 -> 0 | O18: =J18-I18 -> 0 | P18: =L18+M18+N18 -> 16
A19: IDMS-109 | B19: JITHIN PANDIYATH RAJAN PANDIYATH RAMAN RAJAN | C19: 44652 | L19: =E19-D19 -> 0 | M19: =G19-F19 -> 0 | N19: =I19-H19 -> 0 | O19: =J19-I19 -> 0 | P19: =L19+M19+N19 -> 0
A20: IDMS-017 | B20: PRAMOD POINACHI KUNHI RAMAN POINACHI | C20: 44652 | L20: =E20-D20 -> 0 | M20: =G20-F20 -> 0 | N20: =I20-H20 -> 0 | O20: =J20-I20 -> 0 | P20: =L20+M20+N20 -> 0
A21: IDBM-023 | B21: PRABHAKAR PONNAM ANJAIAH PONNAM | C21: 41244 | D21: 45243 | E21: 45289 | L21: =E21-D21 -> 46 | M21: =G21-F21 -> 0 | N21: =I21-H21 -> 0 | O21: =J21-I21 -> 0 | P21: =L21+M21+N21 -> 46
A22: IDBM-026 | B22: MUHAMMAD NIYAS KURIYAKATH MULLAVAPPIL NAZER | C22: 41518 | L22: =E22-D22 -> 0 | M22: =G22-F22 -> 0 | N22: =I22-H22 -> 0 | O22: =J22-I22 -> 0 | P22: =L22+M22+N22 -> 0
A23: IDBM-033 | B23: KABEER MULLAPURATH CHIRAPURATH | C23: 41883 | D23: 45232 | E23: 45262 | L23: =E23-D23 -> 30 | M23: =G23-F23 -> 0 | N23: =I23-H23 -> 0 | O23: =J23-I23 -> 0 | P23: =L23+M23+N23 -> 30
A24: IDMM-034 | B24: GANGARAJAM BAKKAIAH ODNALA | C24: 41913 | D24: 45142 | E24: 45199 | L24: =E24-D24 -> 57 | M24: =G24-F24 -> 0 | N24: =I24-H24 -> 0 | O24: =J24-I24 -> 0 | P24: =L24+M24+N24 -> 57
A25: IDBM-035 | B25: SHIJU VARAKKOTH KUNHIKANNAN NAMBIAR PEEDIKA VALAPPIL | C25: 42005 | L25: =E25-D25 -> 0 | M25: =G25-F25 -> 0 | N25: =I25-H25 -> 0 | O25: =J25-I25 -> 0 | P25: =L25+M25+N25 -> 0
A26: IDMM-028 | B26: MOHAMMED JABID MOIDU KUNHI | C26: 41760 | D26: 45078 | E26: 45139 | L26: =E26-D26 -> 61 | M26: =G26-F26 -> 0 | N26: =I26-H26 -> 0 | O26: =J26-I26 -> 0 | P26: =L26+M26+N26 -> 61
A27: IDBM-029 | B27: SUBHADIN CHUNNUM TAMANG TAMANG | C27: 41760 | L27: =E27-D27 -> 0 | M27: =G27-F27 -> 0 | N27: =I27-H27 -> 0 | O27: =J27-I27 -> 0 | P27: =L27+M27+N27 -> 0
A28: IDMM-021 | B28: ARUN KANNOTHIL MANIKANDAN KANNOTHIL | C28: 40878 | L28: =E28-D28 -> 0 | M28: =G28-F28 -> 0 | N28: =I28-H28 -> 0 | O28: =J28-I28 -> 0 | P28: =L28+M28+N28 -> 0
A29: IDBM-039 | B29: BIPLAB DEB AJIT DEB | C29: 42430 | D29: 45222 | E29: 45267 | L29: =E29-D29 -> 45 | M29: =G29-F29 -> 0 | N29: =I29-H29 -> 0 | O29: =J29-I29 -> 0 | P29: =L29+M29+N29 -> 45
A30: IDBM-040 | B30: PARAMESH CHANDRAIAH NASPURI CHANDRAIAH POSANNA NASPURI | C30: 42522 | D30: 45040 | E30: 45071 | L30: =E30-D30 -> 31 | M30: =G30-F30 -> 0 | N30: =I30-H30 -> 0 | O30: =J30-I30 -> 0 | P30: =L30+M30+N30 -> 31
A31: IDMM-041 | B31: MUHAMMAD USMAN RIAZ AHMAD | C31: 42614 | L31: =E31-D31 -> 0 | M31: =G31-F31 -> 0 | N31: =I31-H31 -> 0 | O31: =J31-I31 -> 0 | P31: =L31+M31+N31 -> 0
A32: IDMM-042 | B32: IMRAN KHAN MUBARAK MOHAMMED KHASIM | C32: 42644 | D32: 44926 | E32: 44982 | L32: =E32-D32 -> 56 | M32: =G32-F32 -> 0 | N32: =I32-H32 -> 0 | O32: =J32-I32 -> 0 | P32: =L32+M32+N32 -> 56
A33: IDBM-043 | B33: MUHAMMAD SABIR MUHAMMAD SAEED | C33: 42675 | L33: =E33-D33 -> 0 | M33: =G33-F33 -> 0 | N33: =I33-H33 -> 0 | O33: =J33-I33 -> 0 | P33: =L33+M33+N33 -> 0
A34: IDBM-048 | B34: SUNIL KUMAR RAM JIVAN | C34: 42948 | L34: =E34-D34 -> 0 | M34: =G34-F34 -> 0 | N34: =I34-H34 -> 0 | O34: =J34-I34 -> 0 | P34: =L34+M34+N34 -> 0
A35: IDMM-049 | B35: UMESH RAMA NAIK RAMA NAIK | C35: 42948 | D35: 44927 | E35: 44930 | L35: =E35-D35 -> 3 | M35: =G35-F35 -> 0 | N35: =I35-H35 -> 0 | O35: =J35-I35 -> 0 | P35: =L35+M35+N35 -> 3
A36: IDMM-050 | B36: AKASH RAVINDRA TAMBEKAR | C36: 42979 | D36: 45043 | E36: 45077 | L36: =E36-D36 -> 34 | M36: =G36-F36 -> 0 | N36: =I36-H36 -> 0 | O36: =J36-I36 -> 0 | P36: =L36+M36+N36 -> 34
A37: IDMM-053 | B37: THIRUPATHI JAINAPURAPU BHEEMAIAH JAINAPURAPU | C37: 43101 | D37: 44992 | E37: 45020 | L37: =E37-D37 -> 28 | M37: =G37-F37 -> 0 | N37: =I37-H37 -> 0 | O37: =J37-I37 -> 0 | P37: =L37+M37+N37 -> 28
A38: IDMM-010 | B38: SAI KUMAR EDUGUNURI NADAIAH EDUGUNURI | C38: 43101 | L38: =E38-D38 -> 0 | M38: =G38-F38 -> 0 | N38: =I38-H38 -> 0 | O38: =J38-I38 -> 0 | P38: =L38+M38+N38 -> 0
A39: IDMM-054 | B39: MOHAMMED TAHIR KHAN PATHAN | C39: 43132 | L39: =E39-D39 -> 0 | M39: =G39-F39 -> 0 | N39: =I39-H39 -> 0 | O39: =J39-I39 -> 0 | P39: =L39+M39+N39 -> 0
A40: IDMM-055 | B40: GANESH KANAUJIA RAM CHANDAR KANAUJIA | C40: 43191 | D40: 44926 | E40: 44989 | L40: =E40-D40 -> 63 | M40: =G40-F40 -> 0 | N40: =I40-H40 -> 0 | O40: =J40-I40 -> 0 | P40: =L40+M40+N40 -> 63
...

Sheet 2022
A1: S.NO. | B1: STAFF NAME | C1: JOINING DATE | D1: 1ST LEAVE | F1: 2ND LEAVE | H1: 3RD LEAVE | J1: 4TH LEAVE | L1: 1 | M1: 2 | N1: 3 | O1: 4 | P1: TOTAL | Q1: Remarks
A2: 1 | B2: KANTESH NIHALCHANDANI | C2: 39295 | D2: 44753 | E2: 44763 | L2: =E2-D2 -> 10 | M2: =G2-F2 -> 0 | N2: =I2-H2 -> 0 | P2: =L2+M2+N2 -> 10
A3: 2 | B3: PAWAN KUMAR | C3: 41883 | D3: 44619 | E3: 44641 | L3: =E3-D3 -> 22 | M3: =G3-F3 -> 0 | N3: =I3-H3 -> 0 | P3: =L3+M3+N3 -> 22
A4: 3 | B4: SREEKANTH | C4: 41883 | D4: 44595 | E4: 44624 | L4: =E4-D4 -> 29 | M4: =G4-F4 -> 0 | N4: =I4-H4 -> 0 | P4: =L4+M4+N4 -> 29
A5: 4 | B5: SANDEEP | C5: 42736 | L5: =E5-D5 -> 0 | M5: =G5-F5 -> 0 | N5: =I5-H5 -> 0 | P5: =L5+M5+N5 -> 0
A6: 5 | B6: ABIRAL THAPA | C6: 40695 | L6: =E6-D6 -> 0 | M6: =G6-F6 -> 0 | N6: =I6-H6 -> 0 | P6: =L6+M6+N6 -> 0
A7: 6 | B7: GAURAV NATHANI | C7: 44317 | L7: =E7-D7 -> 0 | M7: =G7-F7 -> 0 | N7: =I7-H7 -> 0 | P7: =L7+M7+N7 -> 0
A8: 7 | B8: RANJITH KUMAR | C8: 44501 | L8: =E8-D8 -> 0 | M8: =G8-F8 -> 0 | N8: =I8-H8 -> 0 | P8: =L8+M8+N8 -> 0
A9: 8 | B9: JISHNU JOHNY SHEEBA | C9: 44317 | L9: =E9-D9 -> 0 | M9: =G9-F9 -> 0 | N9: =I9-H9 -> 0 | P9: =L9+M9+N9 -> 0
A10: 9 | B10: SANJAY MIRCHUMAL PUNJABI | C10: 39083 | D10: 44652 | E10: 44662 | F10: 44752 | G10: 44757 | L10: =E10-D10 -> 10 | M10: =G10-F10 -> 5 | N10: =I10-H10 -> 0 | P10: =L10+M10+N10 -> 15
A11: 10 | B11: MAHESH CHAINANI | C11: 39083 | D11: 44648 | E11: 44653 | F11: 44764 | G11: 44782 | L11: =E11-D11 -> 5 | M11: =G11-F11 -> 18 | N11: =I11-H11 -> 0 | P11: =L11+M11+N11 -> 23
A12: 11 | B12: JITESH CHAWLA | C12: 39083 | D12: 44760 | E12: 44764 | F12: 44784 | G12: 44796 | L12: =E12-D12 -> 4 | M12: =G12-F12 -> 12 | N12: =I12-H12 -> 0 | P12: =L12+M12+N12 -> 16
A13: 12 | B13: VIJAY KUMAR ASHOK KUMAR | C13: 39142 | D13: 44704 | E13: 44712 | L13: =E13-D13 -> 8 | M13: =G13-F13 -> 0 | N13: =I13-H13 -> 0 | P13: =L13+M13+N13 -> 8
A14: 13 | B14: ASHFAQ AHMED | C14: 42036 | D14: 44562 | E14: 44592 | F14: 44748 | G14: 44760 | H14: 44809 | I14: 44820 | J14: 44919 | K14: 44926 | L14: =E14-D14 -> 30 | M14: =G14-F14 -> 12 | N14: =I14-H14 -> 11 | O14: =K14-J14 -> 7 | P14: =L14+M14+N14+O14 -> 60
A15: 14 | B15: NISHITH SURENDRANATHAN | C15: 39083 | D15: 44767 | E15: 44802 | L15: =E15-D15 -> 35 | M15: =G15-F15 -> 0 | N15: =I15-H15 -> 0 | P15: =L15+M15+N15 -> 35
A16: 15 | B16: ASLAMBHAI SHEIKH | C16: 41334 | D16: 44801 | E16: 44812 | L16: =E16-D16 -> 11 | M16: =G16-F16 -> 0 | N16: =I16-H16 -> 0 | P16: =L16+M16+N16 -> 11
A17: 16 | B17: PRAVEEN KUMAR PALERI PALODAN | C17: 40483 | D17: 44593 | E17: 44613 | L17: =E17-D17 -> 20 | M17: =G17-F17 -> 0 | N17: =I17-H17 -> 0 | P17: =L17+M17+N17 -> 20
A18: 17 | B18: DEEPAK PUSHPAN | C18: 44652 | D18: 44919 | E18: 44926 | L18: =E18-D18 -> 7 | M18: =G18-F18 -> 0 | N18: =I18-H18 -> 0 | P18: =L18+M18+N18 -> 7
A19: 18 | B19: JITHIN PANDIYATH | C19: 44652 | L19: =E19-D19 -> 0 | M19: =G19-F19 -> 0 | N19: =I19-H19 -> 0 | P19: =L19+M19+N19 -> 0
A20: 19 | B20: Pramod Poinachi | C20: 44652 | L20: =E20-D20 -> 0 | M20: =G20-F20 -> 0 | N20: =I20-H20 -> 0 | P20: =L20+M20+N20 -> 0
A21: 20 | B21: Tushan Singh | C21: 44682 | L21: =E21-D21 -> 0 | M21: =G21-F21 -> 0 | N21: =I21-H21 -> 0 | P21: =L21+M21+N21 -> 0
A22: 21 | B22: PRABHAKAR POONAM ANJAIAH POONAM | C22: 41244 | D22: 44706 | E22: 44751 | L22: =E22-D22 -> 45 | M22: =G22-F22 -> 0 | N22: =I22-H22 -> 0 | P22: =L22+M22+N22 -> 45
A23: 22 | B23: MUHAMMAD NIYAS KURIYAKATH | C23: 41518 | D23: 44591 | E23: 44656 | L23: =E23-D23 -> 65 | M23: =G23-F23 -> 0 | N23: =I23-H23 -> 0 | P23: =L23+M23+N23 -> 65
A24: 23 | B24: KABEER | C24: 41883 | D24: 44562 | E24: 44604 | L24: =E24-D24 -> 42 | M24: =G24-F24 -> 0 | N24: =I24-H24 -> 0 | P24: =L24+M24+N24 -> 42
A25: 24 | B25: Gangarajan | C25: 41913 | L25: =E25-D25 -> 0 | M25: =G25-F25 -> 0 | N25: =I25-H25 -> 0 | P25: =L25+M25+N25 -> 0
A26: 25 | B26: SHIJU | C26: 42005 | D26: 44693 | E26: 44755 | L26: =E26-D26 -> 62 | M26: =G26-F26 -> 0 | N26: =I26-H26 -> 0 | P26: =L26+M26+N26 -> 62
A27: 26 | B27: MOHD JABID MOIDU KUNHI | C27: 41760 | L27: =E27-D27 -> 0 | M27: =G27-F27 -> 0 | N27: =I27-H27 -> 0 | P27: =L27+M27+N27 -> 0
A28: 27 | B28: SUBHADIN CHUNNUM TAMANG | C28: 41760 | D28: 44852 | E28: 44862 | L28: =E28-D28 -> 10 | M28: =G28-F28 -> 0 | N28: =I28-H28 -> 0 | P28: =L28+M28+N28 -> 10
A29: 28 | B29: ARUN KANNOTHIL | C29: 40878 | D29: 44804 | E29: 44865 | L29: =E29-D29 -> 61 | M29: =G29-F29 -> 0 | N29: =I29-H29 -> 0 | P29: =L29+M29+N29 -> 61
A30: 29 | B30: BIPLAB DEV | C30: 42430 | D30: 44834 | E30: 44851 | L30: =E30-D30 -> 17 | M30: =G30-F30 -> 0 | N30: =I30-H30 -> 0 | P30: =L30+M30+N30 -> 17
A31: 30 | B31: PARAMESH CHANDRAIAH NASPURI | C31: 42522 | L31: =E31-D31 -> 0 | M31: =G31-F31 -> 0 | N31: =I31-H31 -> 0 | P31: =L31+M31+N31 -> 0
A32: 31 | B32: MUHD USMAN | C32: 42614 | D32: 44674 | E32: 44756 | L32: =E32-D32 -> 82 | M32: =G32-F32 -> 0 | N32: =I32-H32 -> 0 | P32: =L32+M32+N32 -> 82
A33: 32 | B33: IMRAN KHAN | C33: 42644 | D33: 44895 | E33: 44926 | L33: =E33-D33 -> 31 | M33: =G33-F33 -> 0 | N33: =I33-H33 -> 0 | P33: =L33+M33+N33 -> 31
A34: 33 | B34: Muhammad Sabir Muhammad | C34: 42675 | L34: =E34-D34 -> 0 | M34: =G34-F34 -> 0 | N34: =I34-H34 -> 0 | P34: =L34+M34+N34 -> 0
A35: 34 | B35: VIJAY SINGAM | C35: 42856 | D35: 44562 | E35: 44568 | F35: 44665 | G35: 44749 | L35: =E35-D35 -> 6 | M35: =G35-F35 -> 84 | N35: =I35-H35 -> 0 | P35: =L35+M35+N35 -> 90
A36: 35 | B36: SUNIL KUMAR | C36: 42948 | D36: 44656 | E36: 44686 | L36: =E36-D36 -> 30 | M36: =G36-F36 -> 0 | N36: =I36-H36 -> 0 | P36: =L36+M36+N36 -> 30
A37: 36 | B37: UMESH NAIK | C37: 42948 | D37: 44893 | E37: 44926 | L37: =E37-D37 -> 33 | M37: =G37-F37 -> 0 | N37: =I37-H37 -> 0 | P37: =L37+M37+N37 -> 33
A38: 37 | B38: AKASH RAVINDRA TAMBEKAR | C38: 42979 | D38: 44597 | E38: 44660 | L38: =E38-D38 -> 63 | M38: =G38-F38 -> 0 | N38: =I38-H38 -> 0 | P38: =L38+M38+N38 -> 63
A39: 38 | B39: THIRUPATHI JAINAPURAPU | C39: 43101 | D39: 44865 | E39: 44911 | L39: =E39-D39 -> 46 | M39: =G39-F39 -> 0 | N39: =I39-H39 -> 0 | P39: =L39+M39+N39 -> 46
A40: 39 | B40: SAIKUMAR EDUGUNURI | C40: 43101 | D40: 44682 | E40: 44716 | F40: 44768 | G40: 44811 | L40: =E40-D40 -> 34 | M40: =G40-F40 -> 43 | N40: =I40-H40 -> 0 | P40: =L40+M40+N40 -> 77
...

Sheet 2021
A1: S.NO. | B1: STAFF NAME | C1: JOINING DATE | D1: 1ST LEAVE | F1: 2ND LEAVE | H1: 3RD LEAVE | J1: 1 | K1: 2 | L1: 3 | M1: TOTAL
A2: 1 | B2: KANTESH NIHALCHANDANI | C2: 39295 | D2: 44498 | E2: 44519 | J2: =E2-D2 -> 21 | K2: =G2-F2 -> 0 | L2: =I2-H2 -> 0 | M2: =J2+K2+L2 -> 21
A3: 2 | B3: PAWAN KUMAR | C3: 41883 | D3: 44245 | E3: 44276 | J3: =E3-D3 -> 31 | K3: =G3-F3 -> 0 | L3: =I3-H3 -> 0 | M3: =J3+K3+L3 -> 31
A4: 3 | B4: SREEKANTH | C4: 41883 | D4: 44199 | E4: 44234 | J4: =E4-D4 -> 35 | K4: =G4-F4 -> 0 | L4: =I4-H4 -> 0 | M4: =J4+K4+L4 -> 35
A5: 4 | B5: SANDEEP | C5: 42736 | D5: 44281 | E5: 44385 | J5: =E5-D5 -> 104 | K5: =G5-F5 -> 0 | L5: =I5-H5 -> 0 | M5: =J5+K5+L5 -> 104
A6: 5 | B6: ABIRAL THAPA | C6: 40695 | D6: 44480 | E6: 44504 | J6: =E6-D6 -> 24 | K6: =G6-F6 -> 0 | L6: =I6-H6 -> 0 | M6: =J6+K6+L6 -> 24
A7: 6 | B7: GAURAV NATHANI | C7: 44317 | D7: 44505 | E7: 44521 | J7: =E7-D7 -> 16 | K7: =G7-F7 -> 0 | L7: =I7-H7 -> 0 | M7: =J7+K7+L7 -> 16
A8: 7 | B8: RANJITH KUMAR | C8: 44501 | J8: =E8-D8 -> 0 | K8: =G8-F8 -> 0 | L8: =I8-H8 -> 0 | M8: =J8+K8+L8 -> 0
A9: 8 | B9: SANJAY MIRCHUMAL PUNJABI | C9: 39083 | J9: =E9-D9 -> 0 | K9: =G9-F9 -> 0 | L9: =I9-H9 -> 0 | M9: =J9+K9+L9 -> 0
A10: 9 | B10: MAHESH CHAINANI | C10: 39083 | D10: 44427 | E10: 44443 | J10: =E10-D10 -> 16 | K10: =G10-F10 -> 0 | L10: =I10-H10 -> 0 | M10: =J10+K10+L10 -> 16
A11: 10 | B11: JITESH CHAWLA | C11: 39083 | D11: 44450 | E11: 44478 | J11: =E11-D11 -> 28 | K11: =G11-F11 -> 0 | L11: =I11-H11 -> 0 | M11: =J11+K11+L11 -> 28
A12: 11 | B12: VIJAY KUMAR ASHOK KUMAR | C12: 39142 | J12: =E12-D12 -> 0 | K12: =G12-F12 -> 0 | L12: =I12-H12 -> 0 | M12: =J12+K12+L12 -> 0
A13: 12 | B13: ASHFAQ AHMED | C13: 42036 | D13: 44555 | E13: 44561 | J13: =E13-D13 -> 6 | K13: =G13-F13 -> 0 | L13: =I13-H13 -> 0 | M13: =J13+K13+L13 -> 6
A14: 13 | B14: HITESH TEKWANI | C14: 43252 | J14: =E14-D14 -> 0 | K14: =G14-F14 -> 0 | L14: =I14-H14 -> 0 | M14: =J14+K14+L14 -> 0
A15: 14 | B15: NISHITH SURENDRANATHAN | C15: 39083 | J15: =E15-D15 -> 0 | K15: =G15-F15 -> 0 | L15: =I15-H15 -> 0 | M15: =J15+K15+L15 -> 0
A16: 15 | B16: ASLAMBHAI SHEIKH | C16: 41334 | J16: =E16-D16 -> 0 | K16: =G16-F16 -> 0 | L16: =I16-H16 -> 0 | M16: =J16+K16+L16 -> 0
A17: 16 | B17: PRAVEEN KUMAR PALERI PALODAN | C17: 40483 | D17: 44275 | E17: 44304 | J17: =E17-D17 -> 29 | K17: =G17-F17 -> 0 | L17: =I17-H17 -> 0 | M17: =J17+K17+L17 -> 29
A18: 17 | B18: THOUFEEK POTTAMMAL | C18: 40210 | J18: =E18-D18 -> 0 | K18: =G18-F18 -> 0 | L18: =I18-H18 -> 0 | M18: =J18+K18+L18 -> 0
A19: 18 | B19: SAMAD CHONAKADAVATH SADIRI (SALESMAN) | C19: 43647 | J19: =E19-D19 -> 0 | K19: =G19-F19 -> 0 | L19: =I19-H19 -> 0 | M19: =J19+K19+L19 -> 0
A20: 20 | B20: PRABHAKAR POONAM ANJAIAH POONAM | C20: 41244 | D20: 44223 | E20: 44281 | J20: =E20-D20 -> 58 | K20: =G20-F20 -> 0 | L20: =I20-H20 -> 0 | M20: =J20+K20+L20 -> 58
A21: 21 | B21: MUHAMMAD NIYAS KURIYAKATH | C21: 41518 | J21: =E21-D21 -> 0 | K21: =G21-F21 -> 0 | L21: =I21-H21 -> 0 | M21: =J21+K21+L21 -> 0
A22: 22 | B22: KABEER | C22: 41883 | D22: 44524 | E22: 44561 | J22: =E22-D22 -> 37 | K22: =G22-F22 -> 0 | L22: =I22-H22 -> 0 | M22: =J22+K22+L22 -> 37
A23: 23 | B23: Gangarajan | C23: 41913 | D23: 44442 | E23: 44544 | J23: =E23-D23 -> 102 | K23: =G23-F23 -> 0 | L23: =I23-H23 -> 0 | M23: =J23+K23+L23 -> 102 | O23: 44524 | P23: /11/2021
A24: 24 | B24: SHIJU | C24: 42005 | J24: =E24-D24 -> 0 | K24: =G24-F24 -> 0 | L24: =I24-H24 -> 0 | M24: =J24+K24+L24 -> 0
A25: 25 | B25: VIKAS | C25: 42324 | D25: 44256 | E25: 44432 | J25: =E25-D25 -> 176 | K25: =G25-F25 -> 0 | L25: =I25-H25 -> 0 | M25: =J25+K25+L25 -> 176
A26: 26 | B26: MOHD JABID MOIDU KUNHI | C26: 41760 | D26: 44381 | E26: 44442 | J26: =E26-D26 -> 61 | K26: =G26-F26 -> 0 | L26: =I26-H26 -> 0 | M26: =J26+K26+L26 -> 61
A27: 27 | B27: SUBHADIN CHUNNUM TAMANG | C27: 41760 | D27: 44465 | E27: 44531 | J27: =E27-D27 -> 66 | K27: =G27-F27 -> 0 | L27: =I27-H27 -> 0 | M27: =J27+K27+L27 -> 66
A28: 28 | B28: ARUN KANNOTHIL | C28: 40878 | J28: =E28-D28 -> 0 | K28: =G28-F28 -> 0 | L28: =I28-H28 -> 0 | M28: =J28+K28+L28 -> 0
A29: 29 | B29: BIPLAB DEV | C29: 42430 | D29: 44288 | E29: 44435 | J29: =E29-D29 -> 147 | K29: =G29-F29 -> 0 | L29: =I29-H29 -> 0 | M29: =J29+K29+L29 -> 147
A30: 30 | B30: PARAMESH CHANDRAIAH NASPURI | C30: 42522 | D30: 44197 | E30: 44220 | J30: =E30-D30 -> 23 | K30: =G30-F30 -> 0 | L30: =I30-H30 -> 0 | M30: =J30+K30+L30 -> 23
A31: 31 | B31: MUHD USMAN | C31: 42614 | J31: =E31-D31 -> 0 | K31: =G31-F31 -> 0 | L31: =I31-H31 -> 0 | M31: =J31+K31+L31 -> 0
A32: 32 | B32: IMRAN KHAN | C32: 42644 | D32: 44197 | E32: 44227 | J32: =E32-D32 -> 30 | K32: =G32-F32 -> 0 | L32: =I32-H32 -> 0 | M32: =J32+K32+L32 -> 30
A33: 33 | B33: Muhammad Sabir Muhammad | C33: 42675 | D33: 44390 | E33: 44521 | J33: =E33-D33 -> 131 | K33: =G33-F33 -> 0 | L33: =I33-H33 -> 0 | M33: =J33+K33+L33 -> 131
A34: 34 | B34: VIJAY SINGAM | C34: 42856 | D34: 44470 | E34: 44561 | J34: =E34-D34 -> 91 | K34: =G34-F34 -> 0 | L34: =I34-H34 -> 0 | M34: =J34+K34+L34 -> 91
A35: 35 | B35: SUNIL KUMAR | C35: 42948 | D35: 44197 | E35: 44227 | J35: =E35-D35 -> 30 | K35: =G35-F35 -> 0 | L35: =I35-H35 -> 0 | M35: =J35+K35+L35 -> 30
A36: 36 | B36: UMESH NAIK | C36: 42948 | J36: =E36-D36 -> 0 | K36: =G36-F36 -> 0 | L36: =I36-H36 -> 0 | M36: =J36+K36+L36 -> 0
A37: 37 | B37: AKASH RAVINDRA TAMBEKAR | C37: 42979 | J37: =E37-D37 -> 0 | K37: =G37-F37 -> 0 | L37: =I37-H37 -> 0 | M37: =J37+K37+L37 -> 0
A38: 38 | B38: THIRUPATHI JAINAPURAPU | C38: 43101 | J38: =E38-D38 -> 0 | K38: =G38-F38 -> 0 | L38: =I38-H38 -> 0 | M38: =J38+K38+L38 -> 0
A39: 39 | B39: SAIKUMAR EDUGUNURI | C39: 43101 | J39: =E39-D39 -> 0 | K39: =G39-F39 -> 0 | L39: =I39-H39 -> 0 | M39: =J39+K39+L39 -> 0
A40: 40 | B40: TAHER KHAN | C40: 43132 | D40: 44468 | E40: 44492 | J40: =E40-D40 -> 24 | K40: =G40-F40 -> 0 | L40: =I40-H40 -> 0 | M40: =J40+K40+L40 -> 24
...

Sheet 2020
A1: S.NO. | B1: STAFF NAME | C1: JOINING DATE | D1: 1ST LEAVE | F1: 2ND LEAVE | H1: 3RD LEAVE | J1: 1 | K1: 2 | L1: 3 | M1: TOTAL | N1: REMARK
A2: 1 | B2: KANTESH NIHALCHANDANI | C2: 39295 | D2: 0 | E2: 0 | J2: =E2-D2 -> 0 | K2: =G2-F2 -> 0 | L2: =I2-H2 -> 0 | M2: =J2+K2+L2 -> 0
A3: 2 | B3: PAWAN KUMAR | C3: 41883 | D3: 43853 | E3: 43884 | F3: 44174 | G3: 44180 | J3: =E3-D3 -> 31 | K3: =G3-F3 -> 6 | L3: =I3-H3 -> 0 | M3: =J3+K3+L3 -> 37
A4: 3 | B4: SREEKANTH | C4: 41883 | J4: =E4-D4 -> 0 | K4: =G4-F4 -> 0 | L4: =I4-H4 -> 0 | M4: =J4+K4+L4 -> 0
A5: 4 | B5: ARUN KANNOTHIL | C5: 42186 | D5: 43853 | E5: 43899 | J5: =E5-D5 -> 46 | K5: =G5-F5 -> 0 | L5: =I5-H5 -> 0 | M5: =J5+K5+L5 -> 46
A6: 5 | B6: SANDEEP | C6: 42736 | D6: 44156 | E6: 44170 | J6: =E6-D6 -> 14 | K6: =G6-F6 -> 0 | L6: =I6-H6 -> 0 | M6: =J6+K6+L6 -> 14
A7: 6 | B7: ABIRAL THAPA | C7: 40695 | D7: 43889 | E7: 44065 | J7: =E7-D7 -> 176 | K7: =G7-F7 -> 0 | L7: =I7-H7 -> 0 | M7: =J7+K7+L7 -> 176
A8: 7 | B8: SANJAY MIRCHUMAL PUNJABI | C8: 39083 | D8: 43862 | E8: 43865 | J8: =E8-D8 -> 3 | K8: =G8-F8 -> 0 | L8: =I8-H8 -> 0 | M8: =J8+K8+L8 -> 3
A9: 8 | B9: KADER NAMTURUTHI | C9: 39083 | D9: 43867 | E9: 43873 | J9: =E9-D9 -> 6 | K9: =G9-F9 -> 0 | L9: =I9-H9 -> 0 | M9: =J9+K9+L9 -> 6
A10: 9 | B10: MAHESH CHAINANI | C10: 39083 | J10: =E10-D10 -> 0 | K10: =G10-F10 -> 0 | L10: =I10-H10 -> 0 | M10: =J10+K10+L10 -> 0
A11: 10 | B11: JITESH CHAWLA | C11: 39083 | J11: =E11-D11 -> 0 | K11: =G11-F11 -> 0 | L11: =I11-H11 -> 0 | M11: =J11+K11+L11 -> 0
A12: 11 | B12: VIJAY KUMAR ASHOK KUMAR | C12: 39142 | D12: 43831 | E12: 43832 | J12: =E12-D12 -> 1 | K12: =G12-F12 -> 0 | L12: =I12-H12 -> 0 | M12: =J12+K12+L12 -> 1
A13: 12 | B13: ASHFAQ AHMED | C13: 42036 | D13: 43831 | E13: 43832 | F13: 44049 | G13: 44068 | J13: =E13-D13 -> 1 | K13: =G13-F13 -> 19 | L13: =I13-H13 -> 0 | M13: =J13+K13+L13 -> 20
A14: 13 | B14: HITESH TEKWANI | C14: 43252 | F14: 44126 | G14: 44163 | J14: =E14-D14 -> 0 | K14: =G14-F14 -> 37 | L14: =I14-H14 -> 0 | M14: =J14+K14+L14 -> 37
A15: 14 | B15: NISHITH SURENDRANATHAN | C15: 39083 | J15: =E15-D15 -> 0 | K15: =G15-F15 -> 0 | L15: =I15-H15 -> 0 | M15: =J15+K15+L15 -> 0
A16: 15 | B16: ASLAMBHAI SHEIKH | C16: 41334 | J16: =E16-D16 -> 0 | K16: =G16-F16 -> 0 | L16: =I16-H16 -> 0 | M16: =J16+K16+L16 -> 0
A17: 16 | B17: THOUFEEK POTTAMMAL | C17: 40210 | J17: =E17-D17 -> 0 | K17: =G17-F17 -> 0 | L17: =I17-H17 -> 0 | M17: =J17+K17+L17 -> 0
A18: 17 | B18: PRAVEEN KUMAR PALERI PALODAN | C18: 40483 | J18: =E18-D18 -> 0 | K18: =G18-F18 -> 0 | L18: =I18-H18 -> 0 | M18: =J18+K18+L18 -> 0
A19: 18 | B19: SAMAD CHONAKADAVATH SADIRI (SALESMAN) | C19: 43647 | J19: =E19-D19 -> 0 | K19: =G19-F19 -> 0 | L19: =I19-H19 -> 0 | M19: =J19+K19+L19 -> 0
A20: 19 | B20: TAPAN DEV | C20: 41000 | J20: =E20-D20 -> 0 | K20: =G20-F20 -> 0 | L20: =I20-H20 -> 0 | M20: =J20+K20+L20 -> 0
A21: 20 | B21: UMESH PAYYAM VALAPPIL | C21: 41214 | J21: =E21-D21 -> 0 | K21: =G21-F21 -> 0 | L21: =I21-H21 -> 0 | M21: =J21+K21+L21 -> 0
A22: 21 | B22: PRABHAKAR POONAM ANJAIAH POONAM | C22: 41244 | J22: =E22-D22 -> 0 | K22: =G22-F22 -> 0 | L22: =I22-H22 -> 0 | M22: =J22+K22+L22 -> 0
A23: 22 | B23: MUHAMMAD NIYAS KURIYAKATH | C23: 41518 | D23: 43862 | E23: 44040 | J23: =E23-D23 -> 178 | K23: =G23-F23 -> 0 | L23: =I23-H23 -> 0 | M23: =J23+K23+L23 -> 178
A24: 23 | B24: VINOD KUNHAPPU KUNHAPPU | C24: 41548 | D24: 43831 | E24: 43839 | J24: =E24-D24 -> 8 | K24: =G24-F24 -> 0 | L24: =I24-H24 -> 0 | M24: =J24+K24+L24 -> 8
A25: 24 | B25: KABEER | C25: 41883 | D25: 43831 | E25: 43861 | J25: =E25-D25 -> 30 | K25: =G25-F25 -> 0 | L25: =I25-H25 -> 0 | M25: =J25+K25+L25 -> 30
A26: 25 | B26: Gangarajan | C26: 41913 | J26: =E26-D26 -> 0 | K26: =G26-F26 -> 0 | L26: =I26-H26 -> 0 | M26: =J26+K26+L26 -> 0
A27: 26 | B27: SHIJU | C27: 42005 | J27: =E27-D27 -> 0 | K27: =G27-F27 -> 0 | L27: =I27-H27 -> 0 | M27: =J27+K27+L27 -> 0
A28: 27 | B28: Mallesh | C28: 42064 | J28: =E28-D28 -> 0 | K28: =G28-F28 -> 0 | L28: =I28-H28 -> 0 | M28: =J28+K28+L28 -> 0
A29: 28 | B29: AJNAS | C29: 42156 | J29: =E29-D29 -> 0 | K29: =G29-F29 -> 0 | L29: =I29-H29 -> 0 | M29: =J29+K29+L29 -> 0
A30: 29 | B30: Muhammad Shalim | C30: 42248 | D30: 43831 | E30: 43893 | J30: =E30-D30 -> 62 | K30: =G30-F30 -> 0 | L30: =I30-H30 -> 0 | M30: =J30+K30+L30 -> 62
A31: 30 | B31: VIKAS | C31: 42324 | J31: =E31-D31 -> 0 | K31: =G31-F31 -> 0 | L31: =I31-H31 -> 0 | M31: =J31+K31+L31 -> 0
A32: 31 | B32: MOHD JABID MOIDU KUNHI | C32: 41760 | J32: =E32-D32 -> 0 | K32: =G32-F32 -> 0 | L32: =I32-H32 -> 0 | M32: =J32+K32+L32 -> 0
A33: 32 | B33: SUBHADIN CHUNNUM TAMANG | C33: 41760 | J33: =E33-D33 -> 0 | K33: =G33-F33 -> 0 | L33: =I33-H33 -> 0 | M33: =J33+K33+L33 -> 0
